Workbook

Sheet CÁRNICOS
E1: MIÉRCOLES | F1: VIERNES | H1: JUEVES | O1: DÍAS DIFERENCIAL | T1: PRESENTACIÓN | U1: =++CÁRNICOS!CE$10 -> 0 | AC1: =++CÁRNICOS!CF$10 -> 0 | AK1: =++CÁRNICOS!CG$10 -> 0 | AS1: =++CÁRNICOS!CH$10 -> 1 | BA1: =++CÁRNICOS!CI$10 -> 0 | BI1: =++CÁRNICOS!CJ$10 -> 0
D2: CANT. SEDES | E2: =+COUNTA(E$8:E$77) -> 0 | F2: =+COUNTA(F$8:F$77) -> 0 | G2: =+COUNTA(G$8:G$77) -> 0 | H2: =+COUNTA(H$8:H$77) -> 0 | I2: =+COUNTA(I$8:I$77) -> 0 | J2: =+COUNTA(J$8:J$77) -> 0 | O2: DÍAS ESTÁNDAR | T2: PRESENTACIÓN | U2: =+VLOOKUP($N5,CÁRNICOS!$CD$13:$CJ$48,2,FALSE) -> #N/A | AC2: =+VLOOKUP($N5,CÁRNICOS!$CD$13:$CJ$48,3,FALSE) -> #N/A | AK2: =+VLOOKUP($N5,CÁRNICOS!$CD$13:$CJ$48,4,FALSE) -> #N/A | AS2: =+VLOOKUP($N5,CÁRNICOS!$CD$13:$CJ$48,5,FALSE) -> #N/A | BA2: =+VLOOKUP($N5,CÁRNICOS!$CD$13:$CJ$48,6,FALSE) -> #N/A | BI2: =+VLOOKUP($N5,CÁRNICOS!$CD$13:$CJ$48,7,FALSE) -> #N/A | CD2: POLLO DIF | CG2: 90
D3: MENÚ | E3: 8 | F3: 10 | H3: 9 | I3: -- | J3: -- | T3: g | CD3: ROJA DIF | CG3: 70
E4: =+$Z$7 -> CERDO 1 | F4: =+$AH$7 -> CERDO 2 | G4: =+$AP$7 -> RES | H4: =+$AX$7 -> POLLO 1 | I4: =+$BF$7 -> POLLO 2 | J4: =+$BN$7 -> POLLO 3 | K4: OBSERVACIÓN | O4: PRESENTACIÓN BOLSA | T4: =+CONSOLIDADO!$B$8 -> 1000 | U4: =+CONSOLIDADO!D$7 -> CERDO 1 | AA4: 10 | AC4: =+CONSOLIDADO!I$7 -> CERDO 2 | AI4: 10 | AK4: RES | AQ4: 9 | AS4: =+CONSOLIDADO!S$7 -> POLLO 1 | AY4: 10 | BA4: =+CONSOLIDADO!X$7 -> POLLO 2 | BG4: 10 | BI4: =+CONSOLIDADO!AC$7 -> POLLO 3 | BO4: 10 | CD4: POLLO | CE4: 60 | CF4: 75 | CG4: 110 | CH4: 125
T5: DIFERENCIAL | U5: 45 | V5: 45 | W5: 60 | X5: 75 | Y5: 90 | Z5: TOTAL | AA5: TOTAL | AB5: TOTAL | AC5: 45 | AD5: 45 | AE5: 60 | AF5: 75 | AG5: 90 | AH5: TOTAL | AI5: TOTAL | AJ5: TOTAL | AK5: 45 | AL5: 45 | AM5: 60 | AN5: 75 | AO5: 90 | AP5: TOTAL | AQ5: TOTAL | AR5: TOTAL | AS5: 54 | AT5: 54 | AU5: 65 | AV5: 80 | AW5: 100 | AX5: TOTAL | AY5: TOTAL | AZ5: TOTAL | BA5: 54 | BB5: 54 | BC5: 65 | BD5: 80 | BE5: 100 | BF5: TOTAL | BG5: TOTAL | BH5: TOTAL | BI5: 54 | BJ5: 54 | BK5: 65 | BL5: 80 | BM5: 100 | BN5: TOTAL | BO5: TOTAL | BP5: TOTAL | CD5: ROJA | CE5: 52 | CF5: 65 | CG5: 80 | CH5: 100
D6: SUBTOTALES | E6: =+SUBTOTAL(3,E$7:E$77) -> 0 | F6: =+SUBTOTAL(3,F$7:F$77) -> 0 | G6: =+SUBTOTAL(3,G$7:G$77) -> 0 | H6: =+SUBTOTAL(3,H$7:H$77) -> 0 | I6: =+SUBTOTAL(3,I$7:I$77) -> 0 | J6: =+SUBTOTAL(3,J$7:J$77) -> 0 | N6: SEMANA 3 CONSUMO | O6: 20 AL 24 ABRIL | T6: ESTÁNDAR | U6: 45 | V6: 45 | W6: 60 | X6: 75 | Y6: 90 | Z6: TOTAL | AA6: =+Z$7 -> CERDO 1 | AC6: 45 | AD6: 45 | AE6: 60 | AF6: 75 | AG6: 90 | AH6: TOTAL | AI6: =+AH$7 -> CERDO 2 | AK6: 45 | AL6: 45 | AM6: 60 | AN6: 75 | AO6: 90 | AP6: TOTAL | AQ6: =+AP$7 -> RES | AS6: 54 | AT6: 54 | AU6: 65 | AV6: 80 | AW6: 100 | AX6: TOTAL | AY6: =+AX$7 -> POLLO 1 | BA6: 54 | BB6: 54 | BC6: 65 | BD6: 80 | BE6: 100 | BF6: TOTAL | BG6: =+BF$7 -> POLLO 2 | BI6: 54 | BJ6: 54 | BK6: 65 | BL6: 80 | BM6: 100 | BN6: TOTAL | BO6: =+BN$7 -> POLLO 3 | BR6: ETIQUETAS
B7: N° | C7: APS | D7: DIF | L7: RUTA | M7: MUNICIPIO | N7: INSTITUCION | O7: SEDE | P7: APS - R1 | Q7: APS - R1 | R7: APS - R2 | S7: APS - R3 | T7: APS - R4 | U7: G0 | V7: G1 | W7: G2 | X7: G3 | Y7: G4 | Z7: =+U$4 -> CERDO 1 | AA7: BOLSAS | AB7: PESO | AC7: G0 | AD7: G1 | AE7: G2 | AF7: G3 | AG7: G4 | AH7: =+AC$4 -> CERDO 2 | AI7: BOLSAS | AJ7: PESO | AK7: G0 | AL7: G1 | AM7: G2 | AN7: G3 | AO7: G4 | AP7: =+AK$4 -> RES | AQ7: BOLSAS | AR7: PESO | AS7: G0 | AT7: G1 | AU7: G2 | AV7: G3 | AW7: G4 | AX7: =+AS$4 -> POLLO 1 | AY7: BOLSAS | AZ7: PESO | BA7: G0 | BB7: G1 | BC7: G2 | BD7: G3 | BE7: G4 | BF7: =+BA$4 -> POLLO 2 | BG7: BOLSAS | BH7: PESO | BI7: G0 | BJ7: G1 | BK7: G2 | BL7: G3 | BM7: G4 | BN7: =+BI$4 -> POLLO 3 | BO7: BOLSAS | BP7: PESO | BR7: RUTA | BS7: MUNICIPIO | BT7: INSTITUCION | BU7: SEDE | BV7: =+CÁRNICOS!CE$12 -> CERDO 1 | BW7: =+CÁRNICOS!CF$12 -> CERDO 2 | BX7: =+CÁRNICOS!CG$12 -> RES | BY7: =+CÁRNICOS!CH$12 -> POLLO 1 | BZ7: =+CÁRNICOS!CI$12 -> POLLO 2 | CA7: =+CÁRNICOS!CJ$12 -> POLLO 3
B8: =+COUNTIF($M$8:M8,M8) -> 1 | C8: =SUM(P8:T8) -> 42 | D8: X | L8: 7 | M8: AGUADAS | N8: INSTITUCION EDUCATIVA ESCUELA NORMAL SUPERIOR CLAUDINA MUNERA | O8: ESCUELA NORMAL SUPERIOR CLAUDINA MÚNERA (ANEXA) | P8: 0 | Q8: 32 | R8: 10 | S8: 0 | T8: 0 | U8: =+IF($D8<>"",U$6*$P8/$T$4*VLOOKUP($M8,CÁRNICOS!$CD$13:$CJ$48,2,FALSE),U$5*$P8/$T$4*$U$1) -> 0 | V8: =+IF($D8<>"",V$6*$Q8/$T$4*VLOOKUP($M8,CÁRNICOS!$CD$13:$CJ$48,2,FALSE),V$5*$Q8/$T$4*$U$1) -> 0 | W8: =+IF($D8<>"",W$6*$R8/$T$4*VLOOKUP($M8,CÁRNICOS!$CD$13:$CJ$48,2,FALSE),W$5*$R8/$T$4*$U$1) -> 0 | X8: =+IF($D8<>"",X$6*$S8/$T$4*VLOOKUP($M8,CÁRNICOS!$CD$13:$CJ$48,2,FALSE),X$5*$S8/$T$4*$U$1) -> 0 | Y8: =+IF($D8<>"",Y$6*$T8/$T$4*VLOOKUP($M8,CÁRNICOS!$CD$13:$CJ$48,2,FALSE),Y$5*$T8/$T$4*$U$1) -> 0 | Z8: =IF($E8<>"",0,SUM(U8:Y8)) -> 0 | AA8: =+ROUNDUP(Z8/AA$4,0) -> 0 | AB8: =+IF(Z8*AA8=0,0,(ROUNDUP(Z8/AA8,3))) -> 0 | AC8: =+IF($D8<>"",AC$6*$P8/$T$4*VLOOKUP($M8,CÁRNICOS!$CD$13:$CJ$48,3,FALSE),AC$5*$P8/$T$4*$AC$1) -> 0 | AD8: =+IF($D8<>"",AD$6*$Q8/$T$4*VLOOKUP($M8,CÁRNICOS!$CD$13:$CJ$48,3,FALSE),AD$5*$Q8/$T$4*$AC$1) -> 0 | AE8: =+IF($D8<>"",AE$6*$R8/$T$4*VLOOKUP($M8,CÁRNICOS!$CD$13:$CJ$48,3,FALSE),AE$5*$R8/$T$4*$AC$1) -> 0 | AF8: =+IF($D8<>"",AF$6*$S8/$T$4*VLOOKUP($M8,CÁRNICOS!$CD$13:$CJ$48,3,FALSE),AF$5*$S8/$T$4*$AC$1) -> 0 | AG8: =+IF($D8<>"",AG$6*$T8/$T$4*VLOOKUP($M8,CÁRNICOS!$CD$13:$CJ$48,3,FALSE),AG$5*$T8/$T$4*$AC$1) -> 0 | AH8: =IF($F8<>"",0,SUM(AC8:AG8)) -> 0 | AI8: =+ROUNDUP(AH8/AI$4,0) -> 0 | AJ8: =+IF(AH8*AI8=0,0,(ROUNDUP(AH8/AI8,3))) -> 0 | AK8: =+IF($D8<>"",AK$6*$P8/$T$4*VLOOKUP($M8,CÁRNICOS!$CD$13:$CJ$48,4,FALSE),AK$5*$P8/$T$4*$AK$1) -> 0 | AL8: =+IF($D8<>"",AL$6*$Q8/$T$4*VLOOKUP($M8,CÁRNICOS!$CD$13:$CJ$48,4,FALSE),AL$5*$Q8/$T$4*$AK$1) -> 0 | AM8: =+IF($D8<>"",AM$6*$R8/$T$4*VLOOKUP($M8,CÁRNICOS!$CD$13:$CJ$48,4,FALSE),AM$5*$R8/$T$4*$AK$1) -> 0 | AN8: =+IF($D8<>"",AN$6*$S8/$T$4*VLOOKUP($M8,CÁRNICOS!$CD$13:$CJ$48,4,FALSE),AN$5*$S8/$T$4*$AK$1) -> 0 | AO8: =+IF($D8<>"",AO$6*$T8/$T$4*VLOOKUP($M8,CÁRNICOS!$CD$13:$CJ$48,4,FALSE),AO$5*$T8/$T$4*$AK$1) -> 0 | AP8: =IF($G8<>"",0,SUM(AK8:AO8)) -> 0 | AQ8: =+ROUNDUP(AP8/AQ$4,0) -> 0 | AR8: =+IF(AP8*AQ8=0,0,(ROUNDUP(AP8/AQ8,3))) -> 0 | AS8: =+IF($D8<>"",AS$6*$P8/$T$4*VLOOKUP($M8,CÁRNICOS!$CD$13:$CJ$48,5,FALSE),AS$5*$P8/$T$4*$AS$1) -> 0 | AT8: =+IF($D8<>"",AT$6*$Q8/$T$4*VLOOKUP($M8,CÁRNICOS!$CD$13:$CJ$48,5,FALSE),AT$5*$Q8/$T$4*$AS$1) -> 1.728 | AU8: =+IF($D8<>"",AU$6*$R8/$T$4*VLOOKUP($M8,CÁRNICOS!$CD$13:$CJ$48,5,FALSE),AU$5*$R8/$T$4*$AS$1) -> 0.65 | AV8: =+IF($D8<>"",AV$6*$S8/$T$4*VLOOKUP($M8,CÁRNICOS!$CD$13:$CJ$48,5,FALSE),AV$5*$S8/$T$4*$AS$1) -> 0 | AW8: =+IF($D8<>"",AW$6*$T8/$T$4*VLOOKUP($M8,CÁRNICOS!$CD$13:$CJ$48,5,FALSE),AW$5*$T8/$T$4*$AS$1) -> 0 | AX8: =IF($H8<>"",0,SUM(AS8:AW8)) -> 2.378 | AY8: =+ROUNDUP(AX8/AY$4,0) -> 1 | AZ8: =+IF(AX8*AY8=0,0,(ROUNDUP(AX8/AY8,3))) -> 2.378 | BA8: =+IF($D8<>"",BA$6*$P8/$T$4*VLOOKUP($M8,CÁRNICOS!$CD$13:$CJ$48,6,FALSE),BA$5*$P8/$T$4*$BA$1) -> 0 | BB8: =+IF($D8<>"",BB$6*$Q8/$T$4*VLOOKUP($M8,CÁRNICOS!$CD$13:$CJ$48,6,FALSE),BB$5*$Q8/$T$4*$BA$1) -> 0 | BC8: =+IF($D8<>"",BC$6*$R8/$T$4*VLOOKUP($M8,CÁRNICOS!$CD$13:$CJ$48,6,FALSE),BC$5*$R8/$T$4*$BA$1) -> 0 | BD8: =+IF($D8<>"",BD$6*$S8/$T$4*VLOOKUP($M8,CÁRNICOS!$CD$13:$CJ$48,6,FALSE),BD$5*$S8/$T$4*$BA$1) -> 0 | BE8: =+IF($D8<>"",BE$6*$T8/$T$4*VLOOKUP($M8,CÁRNICOS!$CD$13:$CJ$48,6,FALSE),BE$5*$T8/$T$4*$BA$1) -> 0 | BF8: =IF($I8<>"",0,SUM(BA8:BE8)) -> 0 | BG8: =+ROUNDUP(BF8/BG$4,0) -> 0 | BH8: =+IF(BF8*BG8=0,0,(ROUNDUP(BF8/BG8,3))) -> 0 | BI8: =+IF($D8<>"",BI$6*$P8/$T$4*VLOOKUP($M8,CÁRNICOS!$CD$13:$CJ$48,7,FALSE),BI$5*$P8/$T$4*$BI$1) -> 0 | BJ8: =+IF($D8<>"",BJ$6*$Q8/$T$4*VLOOKUP($M8,CÁRNICOS!$CD$13:$CJ$48,7,FALSE),BJ$5*$Q8/$T$4*$BI$1) -> 0 | BK8: =+IF($D8<>"",BK$6*$R8/$T$4*VLOOKUP($M8,CÁRNICOS!$CD$13:$CJ$48,7,FALSE),BK$5*$R8/$T$4*$BI$1) -> 0 | BL8: =+IF($D8<>"",BL$6*$S8/$T$4*VLOOKUP($M8,CÁRNICOS!$CD$13:$CJ$48,7,FALSE),BL$5*$S8/$T$4*$BI$1) -> 0 | BM8: =+IF($D8<>"",BM$6*$T8/$T$4*VLOOKUP($M8,CÁRNICOS!$CD$13:$CJ$48,7,FALSE),BM$5*$T8/$T$4*$BI$1) -> 0 | BN8: =IF($J8<>"",0,SUM(BI8:BM8)) -> 0 | BO8: =+ROUNDUP(BN8/BO$4,0) -> 0 | BP8: =+IF(BN8*BO8=0,0,(ROUNDUP(BN8/BO8,3))) -> 0 | BR8: =+L8 -> 7 | BS8: =+M8 -> AGUADAS | BT8: =+N8 -> INSTITUCION EDUCATIVA ESCUELA NORMAL SUPERIOR CLAUDINA MUNERA | BU8: =+O8 -> ESCUELA NORMAL SUPERIOR CLAUDINA MÚNERA (ANEXA) | BV8: =+Z8 -> 0 | BW8: =+AH8 -> 0 | BX8: =+AP8 -> 0 | BY8: =+AX8 -> 2.378 | BZ8: =+BF8 -> 0 | CA8: =+BN8 -> 0
B9: =+COUNTIF($M$8:M9,M9) -> 2 | C9: =SUM(P9:T9) -> 22 | D9: X | L9: 7 | M9: AGUADAS | N9: INSTITUCION EDUCATIVA ESCUELA NORMAL SUPERIOR CLAUDINA MUNERA | O9: INSTITUCION EDUCATIVA ESCUELA NORMAL SUPERIOR CLAUDINA MUNERA - SEDE PRINCIPAL | P9: 0 | Q9: 0 | R9: 0 | S9: 22 | T9: 0 | U9: =+IF($D9<>"",U$6*$P9/$T$4*VLOOKUP($M9,CÁRNICOS!$CD$13:$CJ$48,2,FALSE),U$5*$P9/$T$4*$U$1) -> 0 | V9: =+IF($D9<>"",V$6*$Q9/$T$4*VLOOKUP($M9,CÁRNICOS!$CD$13:$CJ$48,2,FALSE),V$5*$Q9/$T$4*$U$1) -> 0 | W9: =+IF($D9<>"",W$6*$R9/$T$4*VLOOKUP($M9,CÁRNICOS!$CD$13:$CJ$48,2,FALSE),W$5*$R9/$T$4*$U$1) -> 0 | X9: =+IF($D9<>"",X$6*$S9/$T$4*VLOOKUP($M9,CÁRNICOS!$CD$13:$CJ$48,2,FALSE),X$5*$S9/$T$4*$U$1) -> 0 | Y9: =+IF($D9<>"",Y$6*$T9/$T$4*VLOOKUP($M9,CÁRNICOS!$CD$13:$CJ$48,2,FALSE),Y$5*$T9/$T$4*$U$1) -> 0 | Z9: =IF($E9<>"",0,SUM(U9:Y9)) -> 0 | AA9: =+ROUNDUP(Z9/AA$4,0) -> 0 | AB9: =+IF(Z9*AA9=0,0,(ROUNDUP(Z9/AA9,3))) -> 0 | AC9: =+IF($D9<>"",AC$6*$P9/$T$4*VLOOKUP($M9,CÁRNICOS!$CD$13:$CJ$48,3,FALSE),AC$5*$P9/$T$4*$AC$1) -> 0 | AD9: =+IF($D9<>"",AD$6*$Q9/$T$4*VLOOKUP($M9,CÁRNICOS!$CD$13:$CJ$48,3,FALSE),AD$5*$Q9/$T$4*$AC$1) -> 0 | AE9: =+IF($D9<>"",AE$6*$R9/$T$4*VLOOKUP($M9,CÁRNICOS!$CD$13:$CJ$48,3,FALSE),AE$5*$R9/$T$4*$AC$1) -> 0 | AF9: =+IF($D9<>"",AF$6*$S9/$T$4*VLOOKUP($M9,CÁRNICOS!$CD$13:$CJ$48,3,FALSE),AF$5*$S9/$T$4*$AC$1) -> 0 | AG9: =+IF($D9<>"",AG$6*$T9/$T$4*VLOOKUP($M9,CÁRNICOS!$CD$13:$CJ$48,3,FALSE),AG$5*$T9/$T$4*$AC$1) -> 0 | AH9: =IF($F9<>"",0,SUM(AC9:AG9)) -> 0 | AI9: =+ROUNDUP(AH9/AI$4,0) -> 0 | AJ9: =+IF(AH9*AI9=0,0,(ROUNDUP(AH9/AI9,3))) -> 0 | AK9: =+IF($D9<>"",AK$6*$P9/$T$4*VLOOKUP($M9,CÁRNICOS!$CD$13:$CJ$48,4,FALSE),AK$5*$P9/$T$4*$AK$1) -> 0 | AL9: =+IF($D9<>"",AL$6*$Q9/$T$4*VLOOKUP($M9,CÁRNICOS!$CD$13:$CJ$48,4,FALSE),AL$5*$Q9/$T$4*$AK$1) -> 0 | AM9: =+IF($D9<>"",AM$6*$R9/$T$4*VLOOKUP($M9,CÁRNICOS!$CD$13:$CJ$48,4,FALSE),AM$5*$R9/$T$4*$AK$1) -> 0 | AN9: =+IF($D9<>"",AN$6*$S9/$T$4*VLOOKUP($M9,CÁRNICOS!$CD$13:$CJ$48,4,FALSE),AN$5*$S9/$T$4*$AK$1) -> 0 | AO9: =+IF($D9<>"",AO$6*$T9/$T$4*VLOOKUP($M9,CÁRNICOS!$CD$13:$CJ$48,4,FALSE),AO$5*$T9/$T$4*$AK$1) -> 0 | AP9: =IF($G9<>"",0,SUM(AK9:AO9)) -> 0 | AQ9: =+ROUNDUP(AP9/AQ$4,0) -> 0 | AR9: =+IF(AP9*AQ9=0,0,(ROUNDUP(AP9/AQ9,3))) -> 0 | AS9: =+IF($D9<>"",AS$6*$P9/$T$4*VLOOKUP($M9,CÁRNICOS!$CD$13:$CJ$48,5,FALSE),AS$5*$P9/$T$4*$AS$1) -> 0 | AT9: =+IF($D9<>"",AT$6*$Q9/$T$4*VLOOKUP($M9,CÁRNICOS!$CD$13:$CJ$48,5,FALSE),AT$5*$Q9/$T$4*$AS$1) -> 0 | AU9: =+IF($D9<>"",AU$6*$R9/$T$4*VLOOKUP($M9,CÁRNICOS!$CD$13:$CJ$48,5,FALSE),AU$5*$R9/$T$4*$AS$1) -> 0 | AV9: =+IF($D9<>"",AV$6*$S9/$T$4*VLOOKUP($M9,CÁRNICOS!$CD$13:$CJ$48,5,FALSE),AV$5*$S9/$T$4*$AS$1) -> 1.76 | AW9: =+IF($D9<>"",AW$6*$T9/$T$4*VLOOKUP($M9,CÁRNICOS!$CD$13:$CJ$48,5,FALSE),AW$5*$T9/$T$4*$AS$1) -> 0 | AX9: =IF($H9<>"",0,SUM(AS9:AW9)) -> 1.76 | AY9: =+ROUNDUP(AX9/AY$4,0) -> 1 | AZ9: =+IF(AX9*AY9=0,0,(ROUNDUP(AX9/AY9,3))) -> 1.76 | BA9: =+IF($D9<>"",BA$6*$P9/$T$4*VLOOKUP($M9,CÁRNICOS!$CD$13:$CJ$48,6,FALSE),BA$5*$P9/$T$4*$BA$1) -> 0 | BB9: =+IF($D9<>"",BB$6*$Q9/$T$4*VLOOKUP($M9,CÁRNICOS!$CD$13:$CJ$48,6,FALSE),BB$5*$Q9/$T$4*$BA$1) -> 0 | BC9: =+IF($D9<>"",BC$6*$R9/$T$4*VLOOKUP($M9,CÁRNICOS!$CD$13:$CJ$48,6,FALSE),BC$5*$R9/$T$4*$BA$1) -> 0 | BD9: =+IF($D9<>"",BD$6*$S9/$T$4*VLOOKUP($M9,CÁRNICOS!$CD$13:$CJ$48,6,FALSE),BD$5*$S9/$T$4*$BA$1) -> 0 | BE9: =+IF($D9<>"",BE$6*$T9/$T$4*VLOOKUP($M9,CÁRNICOS!$CD$13:$CJ$48,6,FALSE),BE$5*$T9/$T$4*$BA$1) -> 0 | BF9: =IF($I9<>"",0,SUM(BA9:BE9)) -> 0 | BG9: =+ROUNDUP(BF9/BG$4,0) -> 0 | BH9: =+IF(BF9*BG9=0,0,(ROUNDUP(BF9/BG9,3))) -> 0 | BI9: =+IF($D9<>"",BI$6*$P9/$T$4*VLOOKUP($M9,CÁRNICOS!$CD$13:$CJ$48,7,FALSE),BI$5*$P9/$T$4*$BI$1) -> 0 | BJ9: =+IF($D9<>"",BJ$6*$Q9/$T$4*VLOOKUP($M9,CÁRNICOS!$CD$13:$CJ$48,7,FALSE),BJ$5*$Q9/$T$4*$BI$1) -> 0 | BK9: =+IF($D9<>"",BK$6*$R9/$T$4*VLOOKUP($M9,CÁRNICOS!$CD$13:$CJ$48,7,FALSE),BK$5*$R9/$T$4*$BI$1) -> 0 | BL9: =+IF($D9<>"",BL$6*$S9/$T$4*VLOOKUP($M9,CÁRNICOS!$CD$13:$CJ$48,7,FALSE),BL$5*$S9/$T$4*$BI$1) -> 0 | BM9: =+IF($D9<>"",BM$6*$T9/$T$4*VLOOKUP($M9,CÁRNICOS!$CD$13:$CJ$48,7,FALSE),BM$5*$T9/$T$4*$BI$1) -> 0 | BN9: =IF($J9<>"",0,SUM(BI9:BM9)) -> 0 | BO9: =+ROUNDUP(BN9/BO$4,0) -> 0 | BP9: =+IF(BN9*BO9=0,0,(ROUNDUP(BN9/BO9,3))) -> 0 | BR9: =+L9 -> 7 | BS9: =+M9 -> AGUADAS | BT9: =+N9 -> INSTITUCION EDUCATIVA ESCUELA NORMAL SUPERIOR CLAUDINA MUNERA | BU9: =+O9 -> INSTITUCION EDUCATIVA ESCUELA NORMAL SUPERIOR CLAUDINA MUNERA - SEDE PRINCIPAL | BV9: =+Z9 -> 0 | BW9: =+AH9 -> 0 | BX9: =+AP9 -> 0 | BY9: =+AX9 -> 1.76 | BZ9: =+BF9 -> 0 | CA9: =+BN9 -> 0
B10: =+COUNTIF($M$8:M10,M10) -> 3 | C10: =SUM(P10:T10) -> 61 | D10: X | L10: 7 | M10: AGUADAS | N10: INSTITUCION EDUCATIVA LICEO CLAUDINA MUNERA | O10: ESCUELA SANTA TERESITA | P10: 5 | Q10: 56 | R10: 0 | S10: 0 | T10: 0 | U10: =+IF($D10<>"",U$6*$P10/$T$4*VLOOKUP($M10,CÁRNICOS!$CD$13:$CJ$48,2,FALSE),U$5*$P10/$T$4*$U$1) -> 0 | V10: =+IF($D10<>"",V$6*$Q10/$T$4*VLOOKUP($M10,CÁRNICOS!$CD$13:$CJ$48,2,FALSE),V$5*$Q10/$T$4*$U$1) -> 0 | W10: =+IF($D10<>"",W$6*$R10/$T$4*VLOOKUP($M10,CÁRNICOS!$CD$13:$CJ$48,2,FALSE),W$5*$R10/$T$4*$U$1) -> 0 | X10: =+IF($D10<>"",X$6*$S10/$T$4*VLOOKUP($M10,CÁRNICOS!$CD$13:$CJ$48,2,FALSE),X$5*$S10/$T$4*$U$1) -> 0 | Y10: =+IF($D10<>"",Y$6*$T10/$T$4*VLOOKUP($M10,CÁRNICOS!$CD$13:$CJ$48,2,FALSE),Y$5*$T10/$T$4*$U$1) -> 0 | Z10: =IF($E10<>"",0,SUM(U10:Y10)) -> 0 | AA10: =+ROUNDUP(Z10/AA$4,0) -> 0 | AB10: =+IF(Z10*AA10=0,0,(ROUNDUP(Z10/AA10,3))) -> 0 | AC10: =+IF($D10<>"",AC$6*$P10/$T$4*VLOOKUP($M10,CÁRNICOS!$CD$13:$CJ$48,3,FALSE),AC$5*$P10/$T$4*$AC$1) -> 0 | AD10: =+IF($D10<>"",AD$6*$Q10/$T$4*VLOOKUP($M10,CÁRNICOS!$CD$13:$CJ$48,3,FALSE),AD$5*$Q10/$T$4*$AC$1) -> 0 | AE10: =+IF($D10<>"",AE$6*$R10/$T$4*VLOOKUP($M10,CÁRNICOS!$CD$13:$CJ$48,3,FALSE),AE$5*$R10/$T$4*$AC$1) -> 0 | AF10: =+IF($D10<>"",AF$6*$S10/$T$4*VLOOKUP($M10,CÁRNICOS!$CD$13:$CJ$48,3,FALSE),AF$5*$S10/$T$4*$AC$1) -> 0 | AG10: =+IF($D10<>"",AG$6*$T10/$T$4*VLOOKUP($M10,CÁRNICOS!$CD$13:$CJ$48,3,FALSE),AG$5*$T10/$T$4*$AC$1) -> 0 | AH10: =IF($F10<>"",0,SUM(AC10:AG10)) -> 0 | AI10: =+ROUNDUP(AH10/AI$4,0) -> 0 | AJ10: =+IF(AH10*AI10=0,0,(ROUNDUP(AH10/AI10,3))) -> 0 | AK10: =+IF($D10<>"",AK$6*$P10/$T$4*VLOOKUP($M10,CÁRNICOS!$CD$13:$CJ$48,4,FALSE),AK$5*$P10/$T$4*$AK$1) -> 0 | AL10: =+IF($D10<>"",AL$6*$Q10/$T$4*VLOOKUP($M10,CÁRNICOS!$CD$13:$CJ$48,4,FALSE),AL$5*$Q10/$T$4*$AK$1) -> 0 | AM10: =+IF($D10<>"",AM$6*$R10/$T$4*VLOOKUP($M10,CÁRNICOS!$CD$13:$CJ$48,4,FALSE),AM$5*$R10/$T$4*$AK$1) -> 0 | AN10: =+IF($D10<>"",AN$6*$S10/$T$4*VLOOKUP($M10,CÁRNICOS!$CD$13:$CJ$48,4,FALSE),AN$5*$S10/$T$4*$AK$1) -> 0 | AO10: =+IF($D10<>"",AO$6*$T10/$T$4*VLOOKUP($M10,CÁRNICOS!$CD$13:$CJ$48,4,FALSE),AO$5*$T10/$T$4*$AK$1) -> 0 | AP10: =IF($G10<>"",0,SUM(AK10:AO10)) -> 0 | AQ10: =+ROUNDUP(AP10/AQ$4,0) -> 0 | AR10: =+IF(AP10*AQ10=0,0,(ROUNDUP(AP10/AQ10,3))) -> 0 | AS10: =+IF($D10<>"",AS$6*$P10/$T$4*VLOOKUP($M10,CÁRNICOS!$CD$13:$CJ$48,5,FALSE),AS$5*$P10/$T$4*$AS$1) -> 0.27 | AT10: =+IF($D10<>"",AT$6*$Q10/$T$4*VLOOKUP($M10,CÁRNICOS!$CD$13:$CJ$48,5,FALSE),AT$5*$Q10/$T$4*$AS$1) -> 3.024 | AU10: =+IF($D10<>"",AU$6*$R10/$T$4*VLOOKUP($M10,CÁRNICOS!$CD$13:$CJ$48,5,FALSE),AU$5*$R10/$T$4*$AS$1) -> 0 | AV10: =+IF($D10<>"",AV$6*$S10/$T$4*VLOOKUP($M10,CÁRNICOS!$CD$13:$CJ$48,5,FALSE),AV$5*$S10/$T$4*$AS$1) -> 0 | AW10: =+IF($D10<>"",AW$6*$T10/$T$4*VLOOKUP($M10,CÁRNICOS!$CD$13:$CJ$48,5,FALSE),AW$5*$T10/$T$4*$AS$1) -> 0 | AX10: =IF($H10<>"",0,SUM(AS10:AW10)) -> 3.294 | AY10: =+ROUNDUP(AX10/AY$4,0) -> 1 | AZ10: =+IF(AX10*AY10=0,0,(ROUNDUP(AX10/AY10,3))) -> 3.294 | BA10: =+IF($D10<>"",BA$6*$P10/$T$4*VLOOKUP($M10,CÁRNICOS!$CD$13:$CJ$48,6,FALSE),BA$5*$P10/$T$4*$BA$1) -> 0 | BB10: =+IF($D10<>"",BB$6*$Q10/$T$4*VLOOKUP($M10,CÁRNICOS!$CD$13:$CJ$48,6,FALSE),BB$5*$Q10/$T$4*$BA$1) -> 0 | BC10: =+IF($D10<>"",BC$6*$R10/$T$4*VLOOKUP($M10,CÁRNICOS!$CD$13:$CJ$48,6,FALSE),BC$5*$R10/$T$4*$BA$1) -> 0 | BD10: =+IF($D10<>"",BD$6*$S10/$T$4*VLOOKUP($M10,CÁRNICOS!$CD$13:$CJ$48,6,FALSE),BD$5*$S10/$T$4*$BA$1) -> 0 | BE10: =+IF($D10<>"",BE$6*$T10/$T$4*VLOOKUP($M10,CÁRNICOS!$CD$13:$CJ$48,6,FALSE),BE$5*$T10/$T$4*$BA$1) -> 0 | BF10: =IF($I10<>"",0,SUM(BA10:BE10)) -> 0 | BG10: =+ROUNDUP(BF10/BG$4,0) -> 0 | BH10: =+IF(BF10*BG10=0,0,(ROUNDUP(BF10/BG10,3))) -> 0 | BI10: =+IF($D10<>"",BI$6*$P10/$T$4*VLOOKUP($M10,CÁRNICOS!$CD$13:$CJ$48,7,FALSE),BI$5*$P10/$T$4*$BI$1) -> 0 | BJ10: =+IF($D10<>"",BJ$6*$Q10/$T$4*VLOOKUP($M10,CÁRNICOS!$CD$13:$CJ$48,7,FALSE),BJ$5*$Q10/$T$4*$BI$1) -> 0 | BK10: =+IF($D10<>"",BK$6*$R10/$T$4*VLOOKUP($M10,CÁRNICOS!$CD$13:$CJ$48,7,FALSE),BK$5*$R10/$T$4*$BI$1) -> 0 | BL10: =+IF($D10<>"",BL$6*$S10/$T$4*VLOOKUP($M10,CÁRNICOS!$CD$13:$CJ$48,7,FALSE),BL$5*$S10/$T$4*$BI$1) -> 0 | BM10: =+IF($D10<>"",BM$6*$T10/$T$4*VLOOKUP($M10,CÁRNICOS!$CD$13:$CJ$48,7,FALSE),BM$5*$T10/$T$4*$BI$1) -> 0 | BN10: =IF($J10<>"",0,SUM(BI10:BM10)) -> 0 | BO10: =+ROUNDUP(BN10/BO$4,0) -> 0 | BP10: =+IF(BN10*BO10=0,0,(ROUNDUP(BN10/BO10,3))) -> 0 | BR10: =+L10 -> 7 | BS10: =+M10 -> AGUADAS | BT10: =+N10 -> INSTITUCION EDUCATIVA LICEO CLAUDINA MUNERA | BU10: =+O10 -> ESCUELA SANTA TERESITA | BV10: =+Z10 -> 0 | BW10: =+AH10 -> 0 | BX10: =+AP10 -> 0 | BY10: =+AX10 -> 3.294 | BZ10: =+BF10 -> 0 | CA10: =+BN10 -> 0 | CD10: DIFERENCIAL | CH10: 1
B11: =+COUNTIF($M$8:M11,M11) -> 4 | C11: =SUM(P11:T11) -> 62 | D11: X | L11: 7 | M11: AGUADAS | N11: INSTITUCION EDUCATIVA MARINO GOMEZ ESTRADA | O11: INSTITUCION EDUCATIVA MARINO GOMEZ ESTRADA - SEDE PRINCIPAL (PRIMARIA) | P11: 0 | Q11: 62 | R11: 0 | S11: 0 | T11: 0 | U11: =+IF($D11<>"",U$6*$P11/$T$4*VLOOKUP($M11,CÁRNICOS!$CD$13:$CJ$48,2,FALSE),U$5*$P11/$T$4*$U$1) -> 0 | V11: =+IF($D11<>"",V$6*$Q11/$T$4*VLOOKUP($M11,CÁRNICOS!$CD$13:$CJ$48,2,FALSE),V$5*$Q11/$T$4*$U$1) -> 0 | W11: =+IF($D11<>"",W$6*$R11/$T$4*VLOOKUP($M11,CÁRNICOS!$CD$13:$CJ$48,2,FALSE),W$5*$R11/$T$4*$U$1) -> 0 | X11: =+IF($D11<>"",X$6*$S11/$T$4*VLOOKUP($M11,CÁRNICOS!$CD$13:$CJ$48,2,FALSE),X$5*$S11/$T$4*$U$1) -> 0 | Y11: =+IF($D11<>"",Y$6*$T11/$T$4*VLOOKUP($M11,CÁRNICOS!$CD$13:$CJ$48,2,FALSE),Y$5*$T11/$T$4*$U$1) -> 0 | Z11: =IF($E11<>"",0,SUM(U11:Y11)) -> 0 | AA11: =+ROUNDUP(Z11/AA$4,0) -> 0 | AB11: =+IF(Z11*AA11=0,0,(ROUNDUP(Z11/AA11,3))) -> 0 | AC11: =+IF($D11<>"",AC$6*$P11/$T$4*VLOOKUP($M11,CÁRNICOS!$CD$13:$CJ$48,3,FALSE),AC$5*$P11/$T$4*$AC$1) -> 0 | AD11: =+IF($D11<>"",AD$6*$Q11/$T$4*VLOOKUP($M11,CÁRNICOS!$CD$13:$CJ$48,3,FALSE),AD$5*$Q11/$T$4*$AC$1) -> 0 | AE11: =+IF($D11<>"",AE$6*$R11/$T$4*VLOOKUP($M11,CÁRNICOS!$CD$13:$CJ$48,3,FALSE),AE$5*$R11/$T$4*$AC$1) -> 0 | AF11: =+IF($D11<>"",AF$6*$S11/$T$4*VLOOKUP($M11,CÁRNICOS!$CD$13:$CJ$48,3,FALSE),AF$5*$S11/$T$4*$AC$1) -> 0 | AG11: =+IF($D11<>"",AG$6*$T11/$T$4*VLOOKUP($M11,CÁRNICOS!$CD$13:$CJ$48,3,FALSE),AG$5*$T11/$T$4*$AC$1) -> 0 | AH11: =IF($F11<>"",0,SUM(AC11:AG11)) -> 0 | AI11: =+ROUNDUP(AH11/AI$4,0) -> 0 | AJ11: =+IF(AH11*AI11=0,0,(ROUNDUP(AH11/AI11,3))) -> 0 | AK11: =+IF($D11<>"",AK$6*$P11/$T$4*VLOOKUP($M11,CÁRNICOS!$CD$13:$CJ$48,4,FALSE),AK$5*$P11/$T$4*$AK$1) -> 0 | AL11: =+IF($D11<>"",AL$6*$Q11/$T$4*VLOOKUP($M11,CÁRNICOS!$CD$13:$CJ$48,4,FALSE),AL$5*$Q11/$T$4*$AK$1) -> 0 | AM11: =+IF($D11<>"",AM$6*$R11/$T$4*VLOOKUP($M11,CÁRNICOS!$CD$13:$CJ$48,4,FALSE),AM$5*$R11/$T$4*$AK$1) -> 0 | AN11: =+IF($D11<>"",AN$6*$S11/$T$4*VLOOKUP($M11,CÁRNICOS!$CD$13:$CJ$48,4,FALSE),AN$5*$S11/$T$4*$AK$1) -> 0 | AO11: =+IF($D11<>"",AO$6*$T11/$T$4*VLOOKUP($M11,CÁRNICOS!$CD$13:$CJ$48,4,FALSE),AO$5*$T11/$T$4*$AK$1) -> 0 | AP11: =IF($G11<>"",0,SUM(AK11:AO11)) -> 0 | AQ11: =+ROUNDUP(AP11/AQ$4,0) -> 0 | AR11: =+IF(AP11*AQ11=0,0,(ROUNDUP(AP11/AQ11,3))) -> 0 | AS11: =+IF($D11<>"",AS$6*$P11/$T$4*VLOOKUP($M11,CÁRNICOS!$CD$13:$CJ$48,5,FALSE),AS$5*$P11/$T$4*$AS$1) -> 0 | AT11: =+IF($D11<>"",AT$6*$Q11/$T$4*VLOOKUP($M11,CÁRNICOS!$CD$13:$CJ$48,5,FALSE),AT$5*$Q11/$T$4*$AS$1) -> 3.348 | AU11: =+IF($D11<>"",AU$6*$R11/$T$4*VLOOKUP($M11,CÁRNICOS!$CD$13:$CJ$48,5,FALSE),AU$5*$R11/$T$4*$AS$1) -> 0 | AV11: =+IF($D11<>"",AV$6*$S11/$T$4*VLOOKUP($M11,CÁRNICOS!$CD$13:$CJ$48,5,FALSE),AV$5*$S11/$T$4*$AS$1) -> 0 | AW11: =+IF($D11<>"",AW$6*$T11/$T$4*VLOOKUP($M11,CÁRNICOS!$CD$13:$CJ$48,5,FALSE),AW$5*$T11/$T$4*$AS$1) -> 0 | AX11: =IF($H11<>"",0,SUM(AS11:AW11)) -> 3.348 | AY11: =+ROUNDUP(AX11/AY$4,0) -> 1 | AZ11: =+IF(AX11*AY11=0,0,(ROUNDUP(AX11/AY11,3))) -> 3.348 | BA11: =+IF($D11<>"",BA$6*$P11/$T$4*VLOOKUP($M11,CÁRNICOS!$CD$13:$CJ$48,6,FALSE),BA$5*$P11/$T$4*$BA$1) -> 0 | BB11: =+IF($D11<>"",BB$6*$Q11/$T$4*VLOOKUP($M11,CÁRNICOS!$CD$13:$CJ$48,6,FALSE),BB$5*$Q11/$T$4*$BA$1) -> 0 | BC11: =+IF($D11<>"",BC$6*$R11/$T$4*VLOOKUP($M11,CÁRNICOS!$CD$13:$CJ$48,6,FALSE),BC$5*$R11/$T$4*$BA$1) -> 0 | BD11: =+IF($D11<>"",BD$6*$S11/$T$4*VLOOKUP($M11,CÁRNICOS!$CD$13:$CJ$48,6,FALSE),BD$5*$S11/$T$4*$BA$1) -> 0 | BE11: =+IF($D11<>"",BE$6*$T11/$T$4*VLOOKUP($M11,CÁRNICOS!$CD$13:$CJ$48,6,FALSE),BE$5*$T11/$T$4*$BA$1) -> 0 | BF11: =IF($I11<>"",0,SUM(BA11:BE11)) -> 0 | BG11: =+ROUNDUP(BF11/BG$4,0) -> 0 | BH11: =+IF(BF11*BG11=0,0,(ROUNDUP(BF11/BG11,3))) -> 0 | BI11: =+IF($D11<>"",BI$6*$P11/$T$4*VLOOKUP($M11,CÁRNICOS!$CD$13:$CJ$48,7,FALSE),BI$5*$P11/$T$4*$BI$1) -> 0 | BJ11: =+IF($D11<>"",BJ$6*$Q11/$T$4*VLOOKUP($M11,CÁRNICOS!$CD$13:$CJ$48,7,FALSE),BJ$5*$Q11/$T$4*$BI$1) -> 0 | BK11: =+IF($D11<>"",BK$6*$R11/$T$4*VLOOKUP($M11,CÁRNICOS!$CD$13:$CJ$48,7,FALSE),BK$5*$R11/$T$4*$BI$1) -> 0 | BL11: =+IF($D11<>"",BL$6*$S11/$T$4*VLOOKUP($M11,CÁRNICOS!$CD$13:$CJ$48,7,FALSE),BL$5*$S11/$T$4*$BI$1) -> 0 | BM11: =+IF($D11<>"",BM$6*$T11/$T$4*VLOOKUP($M11,CÁRNICOS!$CD$13:$CJ$48,7,FALSE),BM$5*$T11/$T$4*$BI$1) -> 0 | BN11: =IF($J11<>"",0,SUM(BI11:BM11)) -> 0 | BO11: =+ROUNDUP(BN11/BO$4,0) -> 0 | BP11: =+IF(BN11*BO11=0,0,(ROUNDUP(BN11/BO11,3))) -> 0 | BR11: =+L11 -> 7 | BS11: =+M11 -> AGUADAS | BT11: =+N11 -> INSTITUCION EDUCATIVA MARINO GOMEZ ESTRADA | BU11: =+O11 -> INSTITUCION EDUCATIVA MARINO GOMEZ ESTRADA - SEDE PRINCIPAL (PRIMARIA) | BV11: =+Z11 -> 0 | BW11: =+AH11 -> 0 | BX11: =+AP11 -> 0 | BY11: =+AX11 -> 3.348 | BZ11: =+BF11 -> 0 | CA11: =+BN11 -> 0 | CD11: DÍAS | CH11: 1
B12: =+B11+1 -> 5 | C12: =SUM(P12:T12) -> 53 | D12: X | L12: 2 | M12: ANSERMA | N12: INSTITUCION EDUCATIVA AURELIANO FLOREZ CARDONA | O12: CENTRO EDUCATIVO SIMON BOLIVAR | P12: 41 | Q12: 12 | R12: 0 | S12: 0 | T12: 0 | U12: =+IF($D12<>"",U$6*$P12/$T$4*VLOOKUP($M12,CÁRNICOS!$CD$13:$CJ$48,2,FALSE),U$5*$P12/$T$4*$U$1) -> 0 | V12: =+IF($D12<>"",V$6*$Q12/$T$4*VLOOKUP($M12,CÁRNICOS!$CD$13:$CJ$48,2,FALSE),V$5*$Q12/$T$4*$U$1) -> 0 | W12: =+IF($D12<>"",W$6*$R12/$T$4*VLOOKUP($M12,CÁRNICOS!$CD$13:$CJ$48,2,FALSE),W$5*$R12/$T$4*$U$1) -> 0 | X12: =+IF($D12<>"",X$6*$S12/$T$4*VLOOKUP($M12,CÁRNICOS!$CD$13:$CJ$48,2,FALSE),X$5*$S12/$T$4*$U$1) -> 0 | Y12: =+IF($D12<>"",Y$6*$T12/$T$4*VLOOKUP($M12,CÁRNICOS!$CD$13:$CJ$48,2,FALSE),Y$5*$T12/$T$4*$U$1) -> 0 | Z12: =IF($E12<>"",0,SUM(U12:Y12)) -> 0 | AA12: =+ROUNDUP(Z12/AA$4,0) -> 0 | AB12: =+IF(Z12*AA12=0,0,(ROUNDUP(Z12/AA12,3))) -> 0 | AC12: =+IF($D12<>"",AC$6*$P12/$T$4*VLOOKUP($M12,CÁRNICOS!$CD$13:$CJ$48,3,FALSE),AC$5*$P12/$T$4*$AC$1) -> 0 | AD12: =+IF($D12<>"",AD$6*$Q12/$T$4*VLOOKUP($M12,CÁRNICOS!$CD$13:$CJ$48,3,FALSE),AD$5*$Q12/$T$4*$AC$1) -> 0 | AE12: =+IF($D12<>"",AE$6*$R12/$T$4*VLOOKUP($M12,CÁRNICOS!$CD$13:$CJ$48,3,FALSE),AE$5*$R12/$T$4*$AC$1) -> 0 | AF12: =+IF($D12<>"",AF$6*$S12/$T$4*VLOOKUP($M12,CÁRNICOS!$CD$13:$CJ$48,3,FALSE),AF$5*$S12/$T$4*$AC$1) -> 0 | AG12: =+IF($D12<>"",AG$6*$T12/$T$4*VLOOKUP($M12,CÁRNICOS!$CD$13:$CJ$48,3,FALSE),AG$5*$T12/$T$4*$AC$1) -> 0 | AH12: =IF($F12<>"",0,SUM(AC12:AG12)) -> 0 | AI12: =+ROUNDUP(AH12/AI$4,0) -> 0 | AJ12: =+IF(AH12*AI12=0,0,(ROUNDUP(AH12/AI12,3))) -> 0 | AK12: =+IF($D12<>"",AK$6*$P12/$T$4*VLOOKUP($M12,CÁRNICOS!$CD$13:$CJ$48,4,FALSE),AK$5*$P12/$T$4*$AK$1) -> 0 | AL12: =+IF($D12<>"",AL$6*$Q12/$T$4*VLOOKUP($M12,CÁRNICOS!$CD$13:$CJ$48,4,FALSE),AL$5*$Q12/$T$4*$AK$1) -> 0 | AM12: =+IF($D12<>"",AM$6*$R12/$T$4*VLOOKUP($M12,CÁRNICOS!$CD$13:$CJ$48,4,FALSE),AM$5*$R12/$T$4*$AK$1) -> 0 | AN12: =+IF($D12<>"",AN$6*$S12/$T$4*VLOOKUP($M12,CÁRNICOS!$CD$13:$CJ$48,4,FALSE),AN$5*$S12/$T$4*$AK$1) -> 0 | AO12: =+IF($D12<>"",AO$6*$T12/$T$4*VLOOKUP($M12,CÁRNICOS!$CD$13:$CJ$48,4,FALSE),AO$5*$T12/$T$4*$AK$1) -> 0 | AP12: =IF($G12<>"",0,SUM(AK12:AO12)) -> 0 | AQ12: =+ROUNDUP(AP12/AQ$4,0) -> 0 | AR12: =+IF(AP12*AQ12=0,0,(ROUNDUP(AP12/AQ12,3))) -> 0 | AS12: =+IF($D12<>"",AS$6*$P12/$T$4*VLOOKUP($M12,CÁRNICOS!$CD$13:$CJ$48,5,FALSE),AS$5*$P12/$T$4*$AS$1) -> 2.214 | AT12: =+IF($D12<>"",AT$6*$Q12/$T$4*VLOOKUP($M12,CÁRNICOS!$CD$13:$CJ$48,5,FALSE),AT$5*$Q12/$T$4*$AS$1) -> 0.648 | AU12: =+IF($D12<>"",AU$6*$R12/$T$4*VLOOKUP($M12,CÁRNICOS!$CD$13:$CJ$48,5,FALSE),AU$5*$R12/$T$4*$AS$1) -> 0 | AV12: =+IF($D12<>"",AV$6*$S12/$T$4*VLOOKUP($M12,CÁRNICOS!$CD$13:$CJ$48,5,FALSE),AV$5*$S12/$T$4*$AS$1) -> 0 | AW12: =+IF($D12<>"",AW$6*$T12/$T$4*VLOOKUP($M12,CÁRNICOS!$CD$13:$CJ$48,5,FALSE),AW$5*$T12/$T$4*$AS$1) -> 0 | AX12: =IF($H12<>"",0,SUM(AS12:AW12)) -> 2.862 | AY12: =+ROUNDUP(AX12/AY$4,0) -> 1 | AZ12: =+IF(AX12*AY12=0,0,(ROUNDUP(AX12/AY12,3))) -> 2.862 | BA12: =+IF($D12<>"",BA$6*$P12/$T$4*VLOOKUP($M12,CÁRNICOS!$CD$13:$CJ$48,6,FALSE),BA$5*$P12/$T$4*$BA$1) -> 0 | BB12: =+IF($D12<>"",BB$6*$Q12/$T$4*VLOOKUP($M12,CÁRNICOS!$CD$13:$CJ$48,6,FALSE),BB$5*$Q12/$T$4*$BA$1) -> 0 | BC12: =+IF($D12<>"",BC$6*$R12/$T$4*VLOOKUP($M12,CÁRNICOS!$CD$13:$CJ$48,6,FALSE),BC$5*$R12/$T$4*$BA$1) -> 0 | BD12: =+IF($D12<>"",BD$6*$S12/$T$4*VLOOKUP($M12,CÁRNICOS!$CD$13:$CJ$48,6,FALSE),BD$5*$S12/$T$4*$BA$1) -> 0 | BE12: =+IF($D12<>"",BE$6*$T12/$T$4*VLOOKUP($M12,CÁRNICOS!$CD$13:$CJ$48,6,FALSE),BE$5*$T12/$T$4*$BA$1) -> 0 | BF12: =IF($I12<>"",0,SUM(BA12:BE12)) -> 0 | BG12: =+ROUNDUP(BF12/BG$4,0) -> 0 | BH12: =+IF(BF12*BG12=0,0,(ROUNDUP(BF12/BG12,3))) -> 0 | BI12: =+IF($D12<>"",BI$6*$P12/$T$4*VLOOKUP($M12,CÁRNICOS!$CD$13:$CJ$48,7,FALSE),BI$5*$P12/$T$4*$BI$1) -> 0 | BJ12: =+IF($D12<>"",BJ$6*$Q12/$T$4*VLOOKUP($M12,CÁRNICOS!$CD$13:$CJ$48,7,FALSE),BJ$5*$Q12/$T$4*$BI$1) -> 0 | BK12: =+IF($D12<>"",BK$6*$R12/$T$4*VLOOKUP($M12,CÁRNICOS!$CD$13:$CJ$48,7,FALSE),BK$5*$R12/$T$4*$BI$1) -> 0 | BL12: =+IF($D12<>"",BL$6*$S12/$T$4*VLOOKUP($M12,CÁRNICOS!$CD$13:$CJ$48,7,FALSE),BL$5*$S12/$T$4*$BI$1) -> 0 | BM12: =+IF($D12<>"",BM$6*$T12/$T$4*VLOOKUP($M12,CÁRNICOS!$CD$13:$CJ$48,7,FALSE),BM$5*$T12/$T$4*$BI$1) -> 0 | BN12: =IF($J12<>"",0,SUM(BI12:BM12)) -> 0 | BO12: =+ROUNDUP(BN12/BO$4,0) -> 0 | BP12: =+IF(BN12*BO12=0,0,(ROUNDUP(BN12/BO12,3))) -> 0 | BR12: =+L12 -> 2 | BS12: =+M12 -> ANSERMA | BT12: =+N12 -> INSTITUCION EDUCATIVA AURELIANO FLOREZ CARDONA | BU12: =+O12 -> CENTRO EDUCATIVO SIMON BOLIVAR | BV12: =+Z12 -> 0 | BW12: =+AH12 -> 0 | BX12: =+AP12 -> 0 | BY12: =+AX12 -> 2.862 | BZ12: =+BF12 -> 0 | CA12: =+BN12 -> 0 | CD12: MUNICIPIOS | CE12: =+CONSOLIDADO!D$7 -> CERDO 1 | CF12: =+CONSOLIDADO!I$7 -> CERDO 2 | CG12: RES | CH12: =+CONSOLIDADO!S$7 -> POLLO 1 | CI12: =+CONSOLIDADO!X$7 -> POLLO 2 | CJ12: =+CONSOLIDADO!AC$7 -> POLLO 3
B13: =+B12+1 -> 6 | C13: =SUM(P13:T13) -> 24 | D13: X | L13: 3 | M13: ANSERMA | N13: INSTITUCION EDUCATIVA EL HORRO | O13: SEDE EL PARAISO | P13: 0 | Q13: 24 | R13: 0 | S13: 0 | T13: 0 | U13: =+IF($D13<>"",U$6*$P13/$T$4*VLOOKUP($M13,CÁRNICOS!$CD$13:$CJ$48,2,FALSE),U$5*$P13/$T$4*$U$1) -> 0 | V13: =+IF($D13<>"",V$6*$Q13/$T$4*VLOOKUP($M13,CÁRNICOS!$CD$13:$CJ$48,2,FALSE),V$5*$Q13/$T$4*$U$1) -> 0 | W13: =+IF($D13<>"",W$6*$R13/$T$4*VLOOKUP($M13,CÁRNICOS!$CD$13:$CJ$48,2,FALSE),W$5*$R13/$T$4*$U$1) -> 0 | X13: =+IF($D13<>"",X$6*$S13/$T$4*VLOOKUP($M13,CÁRNICOS!$CD$13:$CJ$48,2,FALSE),X$5*$S13/$T$4*$U$1) -> 0 | Y13: =+IF($D13<>"",Y$6*$T13/$T$4*VLOOKUP($M13,CÁRNICOS!$CD$13:$CJ$48,2,FALSE),Y$5*$T13/$T$4*$U$1) -> 0 | Z13: =IF($E13<>"",0,SUM(U13:Y13)) -> 0 | AA13: =+ROUNDUP(Z13/AA$4,0) -> 0 | AB13: =+IF(Z13*AA13=0,0,(ROUNDUP(Z13/AA13,3))) -> 0 | AC13: =+IF($D13<>"",AC$6*$P13/$T$4*VLOOKUP($M13,CÁRNICOS!$CD$13:$CJ$48,3,FALSE),AC$5*$P13/$T$4*$AC$1) -> 0 | AD13: =+IF($D13<>"",AD$6*$Q13/$T$4*VLOOKUP($M13,CÁRNICOS!$CD$13:$CJ$48,3,FALSE),AD$5*$Q13/$T$4*$AC$1) -> 0 | AE13: =+IF($D13<>"",AE$6*$R13/$T$4*VLOOKUP($M13,CÁRNICOS!$CD$13:$CJ$48,3,FALSE),AE$5*$R13/$T$4*$AC$1) -> 0 | AF13: =+IF($D13<>"",AF$6*$S13/$T$4*VLOOKUP($M13,CÁRNICOS!$CD$13:$CJ$48,3,FALSE),AF$5*$S13/$T$4*$AC$1) -> 0 | AG13: =+IF($D13<>"",AG$6*$T13/$T$4*VLOOKUP($M13,CÁRNICOS!$CD$13:$CJ$48,3,FALSE),AG$5*$T13/$T$4*$AC$1) -> 0 | AH13: =IF($F13<>"",0,SUM(AC13:AG13)) -> 0 | AI13: =+ROUNDUP(AH13/AI$4,0) -> 0 | AJ13: =+IF(AH13*AI13=0,0,(ROUNDUP(AH13/AI13,3))) -> 0 | AK13: =+IF($D13<>"",AK$6*$P13/$T$4*VLOOKUP($M13,CÁRNICOS!$CD$13:$CJ$48,4,FALSE),AK$5*$P13/$T$4*$AK$1) -> 0 | AL13: =+IF($D13<>"",AL$6*$Q13/$T$4*VLOOKUP($M13,CÁRNICOS!$CD$13:$CJ$48,4,FALSE),AL$5*$Q13/$T$4*$AK$1) -> 0 | AM13: =+IF($D13<>"",AM$6*$R13/$T$4*VLOOKUP($M13,CÁRNICOS!$CD$13:$CJ$48,4,FALSE),AM$5*$R13/$T$4*$AK$1) -> 0 | AN13: =+IF($D13<>"",AN$6*$S13/$T$4*VLOOKUP($M13,CÁRNICOS!$CD$13:$CJ$48,4,FALSE),AN$5*$S13/$T$4*$AK$1) -> 0 | AO13: =+IF($D13<>"",AO$6*$T13/$T$4*VLOOKUP($M13,CÁRNICOS!$CD$13:$CJ$48,4,FALSE),AO$5*$T13/$T$4*$AK$1) -> 0 | AP13: =IF($G13<>"",0,SUM(AK13:AO13)) -> 0 | AQ13: =+ROUNDUP(AP13/AQ$4,0) -> 0 | AR13: =+IF(AP13*AQ13=0,0,(ROUNDUP(AP13/AQ13,3))) -> 0 | AS13: =+IF($D13<>"",AS$6*$P13/$T$4*VLOOKUP($M13,CÁRNICOS!$CD$13:$CJ$48,5,FALSE),AS$5*$P13/$T$4*$AS$1) -> 0 | AT13: =+IF($D13<>"",AT$6*$Q13/$T$4*VLOOKUP($M13,CÁRNICOS!$CD$13:$CJ$48,5,FALSE),AT$5*$Q13/$T$4*$AS$1) -> 1.296 | AU13: =+IF($D13<>"",AU$6*$R13/$T$4*VLOOKUP($M13,CÁRNICOS!$CD$13:$CJ$48,5,FALSE),AU$5*$R13/$T$4*$AS$1) -> 0 | AV13: =+IF($D13<>"",AV$6*$S13/$T$4*VLOOKUP($M13,CÁRNICOS!$CD$13:$CJ$48,5,FALSE),AV$5*$S13/$T$4*$AS$1) -> 0 | AW13: =+IF($D13<>"",AW$6*$T13/$T$4*VLOOKUP($M13,CÁRNICOS!$CD$13:$CJ$48,5,FALSE),AW$5*$T13/$T$4*$AS$1) -> 0 | AX13: =IF($H13<>"",0,SUM(AS13:AW13)) -> 1.296 | AY13: =+ROUNDUP(AX13/AY$4,0) -> 1 | AZ13: =+IF(AX13*AY13=0,0,(ROUNDUP(AX13/AY13,3))) -> 1.296 | BA13: =+IF($D13<>"",BA$6*$P13/$T$4*VLOOKUP($M13,CÁRNICOS!$CD$13:$CJ$48,6,FALSE),BA$5*$P13/$T$4*$BA$1) -> 0 | BB13: =+IF($D13<>"",BB$6*$Q13/$T$4*VLOOKUP($M13,CÁRNICOS!$CD$13:$CJ$48,6,FALSE),BB$5*$Q13/$T$4*$BA$1) -> 0 | BC13: =+IF($D13<>"",BC$6*$R13/$T$4*VLOOKUP($M13,CÁRNICOS!$CD$13:$CJ$48,6,FALSE),BC$5*$R13/$T$4*$BA$1) -> 0 | BD13: =+IF($D13<>"",BD$6*$S13/$T$4*VLOOKUP($M13,CÁRNICOS!$CD$13:$CJ$48,6,FALSE),BD$5*$S13/$T$4*$BA$1) -> 0 | BE13: =+IF($D13<>"",BE$6*$T13/$T$4*VLOOKUP($M13,CÁRNICOS!$CD$13:$CJ$48,6,FALSE),BE$5*$T13/$T$4*$BA$1) -> 0 | BF13: =IF($I13<>"",0,SUM(BA13:BE13)) -> 0 | BG13: =+ROUNDUP(BF13/BG$4,0) -> 0 | BH13: =+IF(BF13*BG13=0,0,(ROUNDUP(BF13/BG13,3))) -> 0 | BI13: =+IF($D13<>"",BI$6*$P13/$T$4*VLOOKUP($M13,CÁRNICOS!$CD$13:$CJ$48,7,FALSE),BI$5*$P13/$T$4*$BI$1) -> 0 | BJ13: =+IF($D13<>"",BJ$6*$Q13/$T$4*VLOOKUP($M13,CÁRNICOS!$CD$13:$CJ$48,7,FALSE),BJ$5*$Q13/$T$4*$BI$1) -> 0 | BK13: =+IF($D13<>"",BK$6*$R13/$T$4*VLOOKUP($M13,CÁRNICOS!$CD$13:$CJ$48,7,FALSE),BK$5*$R13/$T$4*$BI$1) -> 0 | BL13: =+IF($D13<>"",BL$6*$S13/$T$4*VLOOKUP($M13,CÁRNICOS!$CD$13:$CJ$48,7,FALSE),BL$5*$S13/$T$4*$BI$1) -> 0 | BM13: =+IF($D13<>"",BM$6*$T13/$T$4*VLOOKUP($M13,CÁRNICOS!$CD$13:$CJ$48,7,FALSE),BM$5*$T13/$T$4*$BI$1) -> 0 | BN13: =IF($J13<>"",0,SUM(BI13:BM13)) -> 0 | BO13: =+ROUNDUP(BN13/BO$4,0) -> 0 | BP13: =+IF(BN13*BO13=0,0,(ROUNDUP(BN13/BO13,3))) -> 0 | BQ13: x | BR13: =+L13 -> 3 | BS13: =+M13 -> ANSERMA | BT13: =+N13 -> INSTITUCION EDUCATIVA EL HORRO | BU13: =+O13 -> SEDE EL PARAISO | BV13: =+Z13 -> 0 | BW13: =+AH13 -> 0 | BX13: =+AP13 -> 0 | BY13: =+AX13 -> 1.296 | BZ13: =+BF13 -> 0 | CA13: =+BN13 -> 0 | CD13: =+CONSOLIDADO!C12 -> LA DORADA | CE13: =+CE$11 -> 0 | CF13: =+CF$11 -> 0 | CG13: =+CG$11 -> 0 | CH13: =+CH$11 -> 1 | CI13: =+CI$11 -> 0 | CJ13: =+CJ$11 -> 0
B14: =+COUNTIF($M$8:M14,M14) -> 1 | C14: =SUM(P14:T14) -> 119 | D14: X | L14: 1 | M14: ARANZAZU | N14: INSTITUCION EDUCATIVA PIO XI | O14: ESCUELA MANUEL GUTIERREZ ROBLEDO | P14: 10 | Q14: 70 | R14: 39 | S14: 0 | T14: 0 | U14: =+IF($D14<>"",U$6*$P14/$T$4*VLOOKUP($M14,CÁRNICOS!$CD$13:$CJ$48,2,FALSE),U$5*$P14/$T$4*$U$1) -> 0 | V14: =+IF($D14<>"",V$6*$Q14/$T$4*VLOOKUP($M14,CÁRNICOS!$CD$13:$CJ$48,2,FALSE),V$5*$Q14/$T$4*$U$1) -> 0 | W14: =+IF($D14<>"",W$6*$R14/$T$4*VLOOKUP($M14,CÁRNICOS!$CD$13:$CJ$48,2,FALSE),W$5*$R14/$T$4*$U$1) -> 0 | X14: =+IF($D14<>"",X$6*$S14/$T$4*VLOOKUP($M14,CÁRNICOS!$CD$13:$CJ$48,2,FALSE),X$5*$S14/$T$4*$U$1) -> 0 | Y14: =+IF($D14<>"",Y$6*$T14/$T$4*VLOOKUP($M14,CÁRNICOS!$CD$13:$CJ$48,2,FALSE),Y$5*$T14/$T$4*$U$1) -> 0 | Z14: =IF($E14<>"",0,SUM(U14:Y14)) -> 0 | AA14: =+ROUNDUP(Z14/AA$4,0) -> 0 | AB14: =+IF(Z14*AA14=0,0,(ROUNDUP(Z14/AA14,3))) -> 0 | AC14: =+IF($D14<>"",AC$6*$P14/$T$4*VLOOKUP($M14,CÁRNICOS!$CD$13:$CJ$48,3,FALSE),AC$5*$P14/$T$4*$AC$1) -> 0 | AD14: =+IF($D14<>"",AD$6*$Q14/$T$4*VLOOKUP($M14,CÁRNICOS!$CD$13:$CJ$48,3,FALSE),AD$5*$Q14/$T$4*$AC$1) -> 0 | AE14: =+IF($D14<>"",AE$6*$R14/$T$4*VLOOKUP($M14,CÁRNICOS!$CD$13:$CJ$48,3,FALSE),AE$5*$R14/$T$4*$AC$1) -> 0 | AF14: =+IF($D14<>"",AF$6*$S14/$T$4*VLOOKUP($M14,CÁRNICOS!$CD$13:$CJ$48,3,FALSE),AF$5*$S14/$T$4*$AC$1) -> 0 | AG14: =+IF($D14<>"",AG$6*$T14/$T$4*VLOOKUP($M14,CÁRNICOS!$CD$13:$CJ$48,3,FALSE),AG$5*$T14/$T$4*$AC$1) -> 0 | AH14: =IF($F14<>"",0,SUM(AC14:AG14)) -> 0 | AI14: =+ROUNDUP(AH14/AI$4,0) -> 0 | AJ14: =+IF(AH14*AI14=0,0,(ROUNDUP(AH14/AI14,3))) -> 0 | AK14: =+IF($D14<>"",AK$6*$P14/$T$4*VLOOKUP($M14,CÁRNICOS!$CD$13:$CJ$48,4,FALSE),AK$5*$P14/$T$4*$AK$1) -> 0 | AL14: =+IF($D14<>"",AL$6*$Q14/$T$4*VLOOKUP($M14,CÁRNICOS!$CD$13:$CJ$48,4,FALSE),AL$5*$Q14/$T$4*$AK$1) -> 0 | AM14: =+IF($D14<>"",AM$6*$R14/$T$4*VLOOKUP($M14,CÁRNICOS!$CD$13:$CJ$48,4,FALSE),AM$5*$R14/$T$4*$AK$1) -> 0 | AN14: =+IF($D14<>"",AN$6*$S14/$T$4*VLOOKUP($M14,CÁRNICOS!$CD$13:$CJ$48,4,FALSE),AN$5*$S14/$T$4*$AK$1) -> 0 | AO14: =+IF($D14<>"",AO$6*$T14/$T$4*VLOOKUP($M14,CÁRNICOS!$CD$13:$CJ$48,4,FALSE),AO$5*$T14/$T$4*$AK$1) -> 0 | AP14: =IF($G14<>"",0,SUM(AK14:AO14)) -> 0 | AQ14: =+ROUNDUP(AP14/AQ$4,0) -> 0 | AR14: =+IF(AP14*AQ14=0,0,(ROUNDUP(AP14/AQ14,3))) -> 0 | AS14: =+IF($D14<>"",AS$6*$P14/$T$4*VLOOKUP($M14,CÁRNICOS!$CD$13:$CJ$48,5,FALSE),AS$5*$P14/$T$4*$AS$1) -> 0.54 | AT14: =+IF($D14<>"",AT$6*$Q14/$T$4*VLOOKUP($M14,CÁRNICOS!$CD$13:$CJ$48,5,FALSE),AT$5*$Q14/$T$4*$AS$1) -> 3.78 | AU14: =+IF($D14<>"",AU$6*$R14/$T$4*VLOOKUP($M14,CÁRNICOS!$CD$13:$CJ$48,5,FALSE),AU$5*$R14/$T$4*$AS$1) -> 2.535 | AV14: =+IF($D14<>"",AV$6*$S14/$T$4*VLOOKUP($M14,CÁRNICOS!$CD$13:$CJ$48,5,FALSE),AV$5*$S14/$T$4*$AS$1) -> 0 | AW14: =+IF($D14<>"",AW$6*$T14/$T$4*VLOOKUP($M14,CÁRNICOS!$CD$13:$CJ$48,5,FALSE),AW$5*$T14/$T$4*$AS$1) -> 0 | AX14: =IF($H14<>"",0,SUM(AS14:AW14)) -> 6.855 | AY14: =+ROUNDUP(AX14/AY$4,0) -> 1 | AZ14: =+IF(AX14*AY14=0,0,(ROUNDUP(AX14/AY14,3))) -> 6.855 | BA14: =+IF($D14<>"",BA$6*$P14/$T$4*VLOOKUP($M14,CÁRNICOS!$CD$13:$CJ$48,6,FALSE),BA$5*$P14/$T$4*$BA$1) -> 0 | BB14: =+IF($D14<>"",BB$6*$Q14/$T$4*VLOOKUP($M14,CÁRNICOS!$CD$13:$CJ$48,6,FALSE),BB$5*$Q14/$T$4*$BA$1) -> 0 | BC14: =+IF($D14<>"",BC$6*$R14/$T$4*VLOOKUP($M14,CÁRNICOS!$CD$13:$CJ$48,6,FALSE),BC$5*$R14/$T$4*$BA$1) -> 0 | BD14: =+IF($D14<>"",BD$6*$S14/$T$4*VLOOKUP($M14,CÁRNICOS!$CD$13:$CJ$48,6,FALSE),BD$5*$S14/$T$4*$BA$1) -> 0 | BE14: =+IF($D14<>"",BE$6*$T14/$T$4*VLOOKUP($M14,CÁRNICOS!$CD$13:$CJ$48,6,FALSE),BE$5*$T14/$T$4*$BA$1) -> 0 | BF14: =IF($I14<>"",0,SUM(BA14:BE14)) -> 0 | BG14: =+ROUNDUP(BF14/BG$4,0) -> 0 | BH14: =+IF(BF14*BG14=0,0,(ROUNDUP(BF14/BG14,3))) -> 0 | BI14: =+IF($D14<>"",BI$6*$P14/$T$4*VLOOKUP($M14,CÁRNICOS!$CD$13:$CJ$48,7,FALSE),BI$5*$P14/$T$4*$BI$1) -> 0 | BJ14: =+IF($D14<>"",BJ$6*$Q14/$T$4*VLOOKUP($M14,CÁRNICOS!$CD$13:$CJ$48,7,FALSE),BJ$5*$Q14/$T$4*$BI$1) -> 0 | BK14: =+IF($D14<>"",BK$6*$R14/$T$4*VLOOKUP($M14,CÁRNICOS!$CD$13:$CJ$48,7,FALSE),BK$5*$R14/$T$4*$BI$1) -> 0 | BL14: =+IF($D14<>"",BL$6*$S14/$T$4*VLOOKUP($M14,CÁRNICOS!$CD$13:$CJ$48,7,FALSE),BL$5*$S14/$T$4*$BI$1) -> 0 | BM14: =+IF($D14<>"",BM$6*$T14/$T$4*VLOOKUP($M14,CÁRNICOS!$CD$13:$CJ$48,7,FALSE),BM$5*$T14/$T$4*$BI$1) -> 0 | BN14: =IF($J14<>"",0,SUM(BI14:BM14)) -> 0 | BO14: =+ROUNDUP(BN14/BO$4,0) -> 0 | BP14: =+IF(BN14*BO14=0,0,(ROUNDUP(BN14/BO14,3))) -> 0 | BQ14: x | BR14: =+L14 -> 1 | BS14: =+M14 -> ARANZAZU | BT14: =+N14 -> INSTITUCION EDUCATIVA PIO XI | BU14: =+O14 -> ESCUELA MANUEL GUTIERREZ ROBLEDO | BV14: =+Z14 -> 0 | BW14: =+AH14 -> 0 | BX14: =+AP14 -> 0 | BY14: =+AX14 -> 6.855 | BZ14: =+BF14 -> 0 | CA14: =+BN14 -> 0 | CD14: =+CONSOLIDADO!C13 -> NORCASIA | CE14: =+CE$11 -> 0 | CF14: =+CF$11 -> 0 | CG14: =+CG$11 -> 0 | CH14: =+CH$11 -> 1 | CI14: =+CI$11 -> 0 | CJ14: =+CJ$11 -> 0
B15: =+COUNTIF($M$8:M15,M15) -> 1 | C15: =SUM(P15:T15) -> 7 | D15: X | L15: 1 | M15: BELALCÁZAR | N15: INSTITUCION EDUCATIVA EL MADROÑO | O15: CONVENTOS | P15: 1 | Q15: 4 | R15: 2 | S15: 0 | T15: 0 | U15: =+IF($D15<>"",U$6*$P15/$T$4*VLOOKUP($M15,CÁRNICOS!$CD$13:$CJ$48,2,FALSE),U$5*$P15/$T$4*$U$1) -> 0 | V15: =+IF($D15<>"",V$6*$Q15/$T$4*VLOOKUP($M15,CÁRNICOS!$CD$13:$CJ$48,2,FALSE),V$5*$Q15/$T$4*$U$1) -> 0 | W15: =+IF($D15<>"",W$6*$R15/$T$4*VLOOKUP($M15,CÁRNICOS!$CD$13:$CJ$48,2,FALSE),W$5*$R15/$T$4*$U$1) -> 0 | X15: =+IF($D15<>"",X$6*$S15/$T$4*VLOOKUP($M15,CÁRNICOS!$CD$13:$CJ$48,2,FALSE),X$5*$S15/$T$4*$U$1) -> 0 | Y15: =+IF($D15<>"",Y$6*$T15/$T$4*VLOOKUP($M15,CÁRNICOS!$CD$13:$CJ$48,2,FALSE),Y$5*$T15/$T$4*$U$1) -> 0 | Z15: =IF($E15<>"",0,SUM(U15:Y15)) -> 0 | AA15: =+ROUNDUP(Z15/AA$4,0) -> 0 | AB15: =+IF(Z15*AA15=0,0,(ROUNDUP(Z15/AA15,3))) -> 0 | AC15: =+IF($D15<>"",AC$6*$P15/$T$4*VLOOKUP($M15,CÁRNICOS!$CD$13:$CJ$48,3,FALSE),AC$5*$P15/$T$4*$AC$1) -> 0 | AD15: =+IF($D15<>"",AD$6*$Q15/$T$4*VLOOKUP($M15,CÁRNICOS!$CD$13:$CJ$48,3,FALSE),AD$5*$Q15/$T$4*$AC$1) -> 0 | AE15: =+IF($D15<>"",AE$6*$R15/$T$4*VLOOKUP($M15,CÁRNICOS!$CD$13:$CJ$48,3,FALSE),AE$5*$R15/$T$4*$AC$1) -> 0 | AF15: =+IF($D15<>"",AF$6*$S15/$T$4*VLOOKUP($M15,CÁRNICOS!$CD$13:$CJ$48,3,FALSE),AF$5*$S15/$T$4*$AC$1) -> 0 | AG15: =+IF($D15<>"",AG$6*$T15/$T$4*VLOOKUP($M15,CÁRNICOS!$CD$13:$CJ$48,3,FALSE),AG$5*$T15/$T$4*$AC$1) -> 0 | AH15: =IF($F15<>"",0,SUM(AC15:AG15)) -> 0 | AI15: =+ROUNDUP(AH15/AI$4,0) -> 0 | AJ15: =+IF(AH15*AI15=0,0,(ROUNDUP(AH15/AI15,3))) -> 0 | AK15: =+IF($D15<>"",AK$6*$P15/$T$4*VLOOKUP($M15,CÁRNICOS!$CD$13:$CJ$48,4,FALSE),AK$5*$P15/$T$4*$AK$1) -> 0 | AL15: =+IF($D15<>"",AL$6*$Q15/$T$4*VLOOKUP($M15,CÁRNICOS!$CD$13:$CJ$48,4,FALSE),AL$5*$Q15/$T$4*$AK$1) -> 0 | AM15: =+IF($D15<>"",AM$6*$R15/$T$4*VLOOKUP($M15,CÁRNICOS!$CD$13:$CJ$48,4,FALSE),AM$5*$R15/$T$4*$AK$1) -> 0 | AN15: =+IF($D15<>"",AN$6*$S15/$T$4*VLOOKUP($M15,CÁRNICOS!$CD$13:$CJ$48,4,FALSE),AN$5*$S15/$T$4*$AK$1) -> 0 | AO15: =+IF($D15<>"",AO$6*$T15/$T$4*VLOOKUP($M15,CÁRNICOS!$CD$13:$CJ$48,4,FALSE),AO$5*$T15/$T$4*$AK$1) -> 0 | AP15: =IF($G15<>"",0,SUM(AK15:AO15)) -> 0 | AQ15: =+ROUNDUP(AP15/AQ$4,0) -> 0 | AR15: =+IF(AP15*AQ15=0,0,(ROUNDUP(AP15/AQ15,3))) -> 0 | AS15: =+IF($D15<>"",AS$6*$P15/$T$4*VLOOKUP($M15,CÁRNICOS!$CD$13:$CJ$48,5,FALSE),AS$5*$P15/$T$4*$AS$1) -> 0.054 | AT15: =+IF($D15<>"",AT$6*$Q15/$T$4*VLOOKUP($M15,CÁRNICOS!$CD$13:$CJ$48,5,FALSE),AT$5*$Q15/$T$4*$AS$1) -> 0.216 | AU15: =+IF($D15<>"",AU$6*$R15/$T$4*VLOOKUP($M15,CÁRNICOS!$CD$13:$CJ$48,5,FALSE),AU$5*$R15/$T$4*$AS$1) -> 0.13 | AV15: =+IF($D15<>"",AV$6*$S15/$T$4*VLOOKUP($M15,CÁRNICOS!$CD$13:$CJ$48,5,FALSE),AV$5*$S15/$T$4*$AS$1) -> 0 | AW15: =+IF($D15<>"",AW$6*$T15/$T$4*VLOOKUP($M15,CÁRNICOS!$CD$13:$CJ$48,5,FALSE),AW$5*$T15/$T$4*$AS$1) -> 0 | AX15: =IF($H15<>"",0,SUM(AS15:AW15)) -> 0.4 | AY15: =+ROUNDUP(AX15/AY$4,0) -> 1 | AZ15: =+IF(AX15*AY15=0,0,(ROUNDUP(AX15/AY15,3))) -> 0.4 | BA15: =+IF($D15<>"",BA$6*$P15/$T$4*VLOOKUP($M15,CÁRNICOS!$CD$13:$CJ$48,6,FALSE),BA$5*$P15/$T$4*$BA$1) -> 0 | BB15: =+IF($D15<>"",BB$6*$Q15/$T$4*VLOOKUP($M15,CÁRNICOS!$CD$13:$CJ$48,6,FALSE),BB$5*$Q15/$T$4*$BA$1) -> 0 | BC15: =+IF($D15<>"",BC$6*$R15/$T$4*VLOOKUP($M15,CÁRNICOS!$CD$13:$CJ$48,6,FALSE),BC$5*$R15/$T$4*$BA$1) -> 0 | BD15: =+IF($D15<>"",BD$6*$S15/$T$4*VLOOKUP($M15,CÁRNICOS!$CD$13:$CJ$48,6,FALSE),BD$5*$S15/$T$4*$BA$1) -> 0 | BE15: =+IF($D15<>"",BE$6*$T15/$T$4*VLOOKUP($M15,CÁRNICOS!$CD$13:$CJ$48,6,FALSE),BE$5*$T15/$T$4*$BA$1) -> 0 | BF15: =IF($I15<>"",0,SUM(BA15:BE15)) -> 0 | BG15: =+ROUNDUP(BF15/BG$4,0) -> 0 | BH15: =+IF(BF15*BG15=0,0,(ROUNDUP(BF15/BG15,3))) -> 0 | BI15: =+IF($D15<>"",BI$6*$P15/$T$4*VLOOKUP($M15,CÁRNICOS!$CD$13:$CJ$48,7,FALSE),BI$5*$P15/$T$4*$BI$1) -> 0 | BJ15: =+IF($D15<>"",BJ$6*$Q15/$T$4*VLOOKUP($M15,CÁRNICOS!$CD$13:$CJ$48,7,FALSE),BJ$5*$Q15/$T$4*$BI$1) -> 0 | BK15: =+IF($D15<>"",BK$6*$R15/$T$4*VLOOKUP($M15,CÁRNICOS!$CD$13:$CJ$48,7,FALSE),BK$5*$R15/$T$4*$BI$1) -> 0 | BL15: =+IF($D15<>"",BL$6*$S15/$T$4*VLOOKUP($M15,CÁRNICOS!$CD$13:$CJ$48,7,FALSE),BL$5*$S15/$T$4*$BI$1) -> 0 | BM15: =+IF($D15<>"",BM$6*$T15/$T$4*VLOOKUP($M15,CÁRNICOS!$CD$13:$CJ$48,7,FALSE),BM$5*$T15/$T$4*$BI$1) -> 0 | BN15: =IF($J15<>"",0,SUM(BI15:BM15)) -> 0 | BO15: =+ROUNDUP(BN15/BO$4,0) -> 0 | BP15: =+IF(BN15*BO15=0,0,(ROUNDUP(BN15/BO15,3))) -> 0 | BQ15: x | BR15: =+L15 -> 1 | BS15: =+M15 -> BELALCÁZAR | BT15: =+N15 -> INSTITUCION EDUCATIVA EL MADROÑO | BU15: =+O15 -> CONVENTOS | BV15: =+Z15 -> 0 | BW15: =+AH15 -> 0 | BX15: =+AP15 -> 0 | BY15: =+AX15 -> 0.4 | BZ15: =+BF15 -> 0 | CA15: =+BN15 -> 0 | CD15: =+CONSOLIDADO!C14 -> SAMANÁ | CE15: =+CE$11 -> 0 | CF15: =+CF$11 -> 0 | CG15: =+CG$11 -> 0 | CH15: =+CH$11 -> 1 | CI15: =+CI$11 -> 0 | CJ15: =+CJ$11 -> 0
B16: =+COUNTIF($M$8:M16,M16) -> 2 | C16: =SUM(P16:T16) -> 21 | D16: X | L16: 1 | M16: BELALCÁZAR | N16: INSTITUCION EDUCATIVA EL MADROÑO | O16: INSTITUCION EDUCATIVA EL MADROÑO - SEDE PRINCIPAL | P16: 0 | Q16: 0 | R16: 0 | S16: 21 | T16: 0 | U16: =+IF($D16<>"",U$6*$P16/$T$4*VLOOKUP($M16,CÁRNICOS!$CD$13:$CJ$48,2,FALSE),U$5*$P16/$T$4*$U$1) -> 0 | V16: =+IF($D16<>"",V$6*$Q16/$T$4*VLOOKUP($M16,CÁRNICOS!$CD$13:$CJ$48,2,FALSE),V$5*$Q16/$T$4*$U$1) -> 0 | W16: =+IF($D16<>"",W$6*$R16/$T$4*VLOOKUP($M16,CÁRNICOS!$CD$13:$CJ$48,2,FALSE),W$5*$R16/$T$4*$U$1) -> 0 | X16: =+IF($D16<>"",X$6*$S16/$T$4*VLOOKUP($M16,CÁRNICOS!$CD$13:$CJ$48,2,FALSE),X$5*$S16/$T$4*$U$1) -> 0 | Y16: =+IF($D16<>"",Y$6*$T16/$T$4*VLOOKUP($M16,CÁRNICOS!$CD$13:$CJ$48,2,FALSE),Y$5*$T16/$T$4*$U$1) -> 0 | Z16: =IF($E16<>"",0,SUM(U16:Y16)) -> 0 | AA16: =+ROUNDUP(Z16/AA$4,0) -> 0 | AB16: =+IF(Z16*AA16=0,0,(ROUNDUP(Z16/AA16,3))) -> 0 | AC16: =+IF($D16<>"",AC$6*$P16/$T$4*VLOOKUP($M16,CÁRNICOS!$CD$13:$CJ$48,3,FALSE),AC$5*$P16/$T$4*$AC$1) -> 0 | AD16: =+IF($D16<>"",AD$6*$Q16/$T$4*VLOOKUP($M16,CÁRNICOS!$CD$13:$CJ$48,3,FALSE),AD$5*$Q16/$T$4*$AC$1) -> 0 | AE16: =+IF($D16<>"",AE$6*$R16/$T$4*VLOOKUP($M16,CÁRNICOS!$CD$13:$CJ$48,3,FALSE),AE$5*$R16/$T$4*$AC$1) -> 0 | AF16: =+IF($D16<>"",AF$6*$S16/$T$4*VLOOKUP($M16,CÁRNICOS!$CD$13:$CJ$48,3,FALSE),AF$5*$S16/$T$4*$AC$1) -> 0 | AG16: =+IF($D16<>"",AG$6*$T16/$T$4*VLOOKUP($M16,CÁRNICOS!$CD$13:$CJ$48,3,FALSE),AG$5*$T16/$T$4*$AC$1) -> 0 | AH16: =IF($F16<>"",0,SUM(AC16:AG16)) -> 0 | AI16: =+ROUNDUP(AH16/AI$4,0) -> 0 | AJ16: =+IF(AH16*AI16=0,0,(ROUNDUP(AH16/AI16,3))) -> 0 | AK16: =+IF($D16<>"",AK$6*$P16/$T$4*VLOOKUP($M16,CÁRNICOS!$CD$13:$CJ$48,4,FALSE),AK$5*$P16/$T$4*$AK$1) -> 0 | AL16: =+IF($D16<>"",AL$6*$Q16/$T$4*VLOOKUP($M16,CÁRNICOS!$CD$13:$CJ$48,4,FALSE),AL$5*$Q16/$T$4*$AK$1) -> 0 | AM16: =+IF($D16<>"",AM$6*$R16/$T$4*VLOOKUP($M16,CÁRNICOS!$CD$13:$CJ$48,4,FALSE),AM$5*$R16/$T$4*$AK$1) -> 0 | AN16: =+IF($D16<>"",AN$6*$S16/$T$4*VLOOKUP($M16,CÁRNICOS!$CD$13:$CJ$48,4,FALSE),AN$5*$S16/$T$4*$AK$1) -> 0 | AO16: =+IF($D16<>"",AO$6*$T16/$T$4*VLOOKUP($M16,CÁRNICOS!$CD$13:$CJ$48,4,FALSE),AO$5*$T16/$T$4*$AK$1) -> 0 | AP16: =IF($G16<>"",0,SUM(AK16:AO16)) -> 0 | AQ16: =+ROUNDUP(AP16/AQ$4,0) -> 0 | AR16: =+IF(AP16*AQ16=0,0,(ROUNDUP(AP16/AQ16,3))) -> 0 | AS16: =+IF($D16<>"",AS$6*$P16/$T$4*VLOOKUP($M16,CÁRNICOS!$CD$13:$CJ$48,5,FALSE),AS$5*$P16/$T$4*$AS$1) -> 0 | AT16: =+IF($D16<>"",AT$6*$Q16/$T$4*VLOOKUP($M16,CÁRNICOS!$CD$13:$CJ$48,5,FALSE),AT$5*$Q16/$T$4*$AS$1) -> 0 | AU16: =+IF($D16<>"",AU$6*$R16/$T$4*VLOOKUP($M16,CÁRNICOS!$CD$13:$CJ$48,5,FALSE),AU$5*$R16/$T$4*$AS$1) -> 0 | AV16: =+IF($D16<>"",AV$6*$S16/$T$4*VLOOKUP($M16,CÁRNICOS!$CD$13:$CJ$48,5,FALSE),AV$5*$S16/$T$4*$AS$1) -> 1.68 | AW16: =+IF($D16<>"",AW$6*$T16/$T$4*VLOOKUP($M16,CÁRNICOS!$CD$13:$CJ$48,5,FALSE),AW$5*$T16/$T$4*$AS$1) -> 0 | AX16: =IF($H16<>"",0,SUM(AS16:AW16)) -> 1.68 | AY16: =+ROUNDUP(AX16/AY$4,0) -> 1 | AZ16: =+IF(AX16*AY16=0,0,(ROUNDUP(AX16/AY16,3))) -> 1.68 | BA16: =+IF($D16<>"",BA$6*$P16/$T$4*VLOOKUP($M16,CÁRNICOS!$CD$13:$CJ$48,6,FALSE),BA$5*$P16/$T$4*$BA$1) -> 0 | BB16: =+IF($D16<>"",BB$6*$Q16/$T$4*VLOOKUP($M16,CÁRNICOS!$CD$13:$CJ$48,6,FALSE),BB$5*$Q16/$T$4*$BA$1) -> 0 | BC16: =+IF($D16<>"",BC$6*$R16/$T$4*VLOOKUP($M16,CÁRNICOS!$CD$13:$CJ$48,6,FALSE),BC$5*$R16/$T$4*$BA$1) -> 0 | BD16: =+IF($D16<>"",BD$6*$S16/$T$4*VLOOKUP($M16,CÁRNICOS!$CD$13:$CJ$48,6,FALSE),BD$5*$S16/$T$4*$BA$1) -> 0 | BE16: =+IF($D16<>"",BE$6*$T16/$T$4*VLOOKUP($M16,CÁRNICOS!$CD$13:$CJ$48,6,FALSE),BE$5*$T16/$T$4*$BA$1) -> 0 | BF16: =IF($I16<>"",0,SUM(BA16:BE16)) -> 0 | BG16: =+ROUNDUP(BF16/BG$4,0) -> 0 | BH16: =+IF(BF16*BG16=0,0,(ROUNDUP(BF16/BG16,3))) -> 0 | BI16: =+IF($D16<>"",BI$6*$P16/$T$4*VLOOKUP($M16,CÁRNICOS!$CD$13:$CJ$48,7,FALSE),BI$5*$P16/$T$4*$BI$1) -> 0 | BJ16: =+IF($D16<>"",BJ$6*$Q16/$T$4*VLOOKUP($M16,CÁRNICOS!$CD$13:$CJ$48,7,FALSE),BJ$5*$Q16/$T$4*$BI$1) -> 0 | BK16: =+IF($D16<>"",BK$6*$R16/$T$4*VLOOKUP($M16,CÁRNICOS!$CD$13:$CJ$48,7,FALSE),BK$5*$R16/$T$4*$BI$1) -> 0 | BL16: =+IF($D16<>"",BL$6*$S16/$T$4*VLOOKUP($M16,CÁRNICOS!$CD$13:$CJ$48,7,FALSE),BL$5*$S16/$T$4*$BI$1) -> 0 | BM16: =+IF($D16<>"",BM$6*$T16/$T$4*VLOOKUP($M16,CÁRNICOS!$CD$13:$CJ$48,7,FALSE),BM$5*$T16/$T$4*$BI$1) -> 0 | BN16: =IF($J16<>"",0,SUM(BI16:BM16)) -> 0 | BO16: =+ROUNDUP(BN16/BO$4,0) -> 0 | BP16: =+IF(BN16*BO16=0,0,(ROUNDUP(BN16/BO16,3))) -> 0 | BR16: =+L16 -> 1 | BS16: =+M16 -> BELALCÁZAR | BT16: =+N16 -> INSTITUCION EDUCATIVA EL MADROÑO | BU16: =+O16 -> INSTITUCION EDUCATIVA EL MADROÑO - SEDE PRINCIPAL | BV16: =+Z16 -> 0 | BW16: =+AH16 -> 0 | BX16: =+AP16 -> 0 | BY16: =+AX16 -> 1.68 | BZ16: =+BF16 -> 0 | CA16: =+BN16 -> 0 | CD16: =+CONSOLIDADO!C15 -> SAMANÁ (FLORENCIA) | CE16: =+CE$11 -> 0 | CF16: =+CF$11 -> 0 | CG16: =+CG$11 -> 0 | CH16: =+CH$11 -> 1 | CI16: =+CI$11 -> 0 | CJ16: =+CJ$11 -> 0
B17: =+COUNTIF($M$8:M17,M17) -> 3 | C17: =SUM(P17:T17) -> 47 | D17: X | L17: 4 | M17: BELALCÁZAR | N17: INSTITUCION EDUCATIVA CRISTO REY | O17: CENTRO DOCENTE MANUELA BELTRAN | P17: 47 | Q17: 0 | R17: 0 | S17: 0 | T17: 0 | U17: =+IF($D17<>"",U$6*$P17/$T$4*VLOOKUP($M17,CÁRNICOS!$CD$13:$CJ$48,2,FALSE),U$5*$P17/$T$4*$U$1) -> 0 | V17: =+IF($D17<>"",V$6*$Q17/$T$4*VLOOKUP($M17,CÁRNICOS!$CD$13:$CJ$48,2,FALSE),V$5*$Q17/$T$4*$U$1) -> 0 | W17: =+IF($D17<>"",W$6*$R17/$T$4*VLOOKUP($M17,CÁRNICOS!$CD$13:$CJ$48,2,FALSE),W$5*$R17/$T$4*$U$1) -> 0 | X17: =+IF($D17<>"",X$6*$S17/$T$4*VLOOKUP($M17,CÁRNICOS!$CD$13:$CJ$48,2,FALSE),X$5*$S17/$T$4*$U$1) -> 0 | Y17: =+IF($D17<>"",Y$6*$T17/$T$4*VLOOKUP($M17,CÁRNICOS!$CD$13:$CJ$48,2,FALSE),Y$5*$T17/$T$4*$U$1) -> 0 | Z17: =IF($E17<>"",0,SUM(U17:Y17)) -> 0 | AA17: =+ROUNDUP(Z17/AA$4,0) -> 0 | AB17: =+IF(Z17*AA17=0,0,(ROUNDUP(Z17/AA17,3))) -> 0 | AC17: =+IF($D17<>"",AC$6*$P17/$T$4*VLOOKUP($M17,CÁRNICOS!$CD$13:$CJ$48,3,FALSE),AC$5*$P17/$T$4*$AC$1) -> 0 | AD17: =+IF($D17<>"",AD$6*$Q17/$T$4*VLOOKUP($M17,CÁRNICOS!$CD$13:$CJ$48,3,FALSE),AD$5*$Q17/$T$4*$AC$1) -> 0 | AE17: =+IF($D17<>"",AE$6*$R17/$T$4*VLOOKUP($M17,CÁRNICOS!$CD$13:$CJ$48,3,FALSE),AE$5*$R17/$T$4*$AC$1) -> 0 | AF17: =+IF($D17<>"",AF$6*$S17/$T$4*VLOOKUP($M17,CÁRNICOS!$CD$13:$CJ$48,3,FALSE),AF$5*$S17/$T$4*$AC$1) -> 0 | AG17: =+IF($D17<>"",AG$6*$T17/$T$4*VLOOKUP($M17,CÁRNICOS!$CD$13:$CJ$48,3,FALSE),AG$5*$T17/$T$4*$AC$1) -> 0 | AH17: =IF($F17<>"",0,SUM(AC17:AG17)) -> 0 | AI17: =+ROUNDUP(AH17/AI$4,0) -> 0 | AJ17: =+IF(AH17*AI17=0,0,(ROUNDUP(AH17/AI17,3))) -> 0 | AK17: =+IF($D17<>"",AK$6*$P17/$T$4*VLOOKUP($M17,CÁRNICOS!$CD$13:$CJ$48,4,FALSE),AK$5*$P17/$T$4*$AK$1) -> 0 | AL17: =+IF($D17<>"",AL$6*$Q17/$T$4*VLOOKUP($M17,CÁRNICOS!$CD$13:$CJ$48,4,FALSE),AL$5*$Q17/$T$4*$AK$1) -> 0 | AM17: =+IF($D17<>"",AM$6*$R17/$T$4*VLOOKUP($M17,CÁRNICOS!$CD$13:$CJ$48,4,FALSE),AM$5*$R17/$T$4*$AK$1) -> 0 | AN17: =+IF($D17<>"",AN$6*$S17/$T$4*VLOOKUP($M17,CÁRNICOS!$CD$13:$CJ$48,4,FALSE),AN$5*$S17/$T$4*$AK$1) -> 0 | AO17: =+IF($D17<>"",AO$6*$T17/$T$4*VLOOKUP($M17,CÁRNICOS!$CD$13:$CJ$48,4,FALSE),AO$5*$T17/$T$4*$AK$1) -> 0 | AP17: =IF($G17<>"",0,SUM(AK17:AO17)) -> 0 | AQ17: =+ROUNDUP(AP17/AQ$4,0) -> 0 | AR17: =+IF(AP17*AQ17=0,0,(ROUNDUP(AP17/AQ17,3))) -> 0 | AS17: =+IF($D17<>"",AS$6*$P17/$T$4*VLOOKUP($M17,CÁRNICOS!$CD$13:$CJ$48,5,FALSE),AS$5*$P17/$T$4*$AS$1) -> 2.538 | AT17: =+IF($D17<>"",AT$6*$Q17/$T$4*VLOOKUP($M17,CÁRNICOS!$CD$13:$CJ$48,5,FALSE),AT$5*$Q17/$T$4*$AS$1) -> 0 | AU17: =+IF($D17<>"",AU$6*$R17/$T$4*VLOOKUP($M17,CÁRNICOS!$CD$13:$CJ$48,5,FALSE),AU$5*$R17/$T$4*$AS$1) -> 0 | AV17: =+IF($D17<>"",AV$6*$S17/$T$4*VLOOKUP($M17,CÁRNICOS!$CD$13:$CJ$48,5,FALSE),AV$5*$S17/$T$4*$AS$1) -> 0 | AW17: =+IF($D17<>"",AW$6*$T17/$T$4*VLOOKUP($M17,CÁRNICOS!$CD$13:$CJ$48,5,FALSE),AW$5*$T17/$T$4*$AS$1) -> 0 | AX17: =IF($H17<>"",0,SUM(AS17:AW17)) -> 2.538 | AY17: =+ROUNDUP(AX17/AY$4,0) -> 1 | AZ17: =+IF(AX17*AY17=0,0,(ROUNDUP(AX17/AY17,3))) -> 2.538 | BA17: =+IF($D17<>"",BA$6*$P17/$T$4*VLOOKUP($M17,CÁRNICOS!$CD$13:$CJ$48,6,FALSE),BA$5*$P17/$T$4*$BA$1) -> 0 | BB17: =+IF($D17<>"",BB$6*$Q17/$T$4*VLOOKUP($M17,CÁRNICOS!$CD$13:$CJ$48,6,FALSE),BB$5*$Q17/$T$4*$BA$1) -> 0 | BC17: =+IF($D17<>"",BC$6*$R17/$T$4*VLOOKUP($M17,CÁRNICOS!$CD$13:$CJ$48,6,FALSE),BC$5*$R17/$T$4*$BA$1) -> 0 | BD17: =+IF($D17<>"",BD$6*$S17/$T$4*VLOOKUP($M17,CÁRNICOS!$CD$13:$CJ$48,6,FALSE),BD$5*$S17/$T$4*$BA$1) -> 0 | BE17: =+IF($D17<>"",BE$6*$T17/$T$4*VLOOKUP($M17,CÁRNICOS!$CD$13:$CJ$48,6,FALSE),BE$5*$T17/$T$4*$BA$1) -> 0 | BF17: =IF($I17<>"",0,SUM(BA17:BE17)) -> 0 | BG17: =+ROUNDUP(BF17/BG$4,0) -> 0 | BH17: =+IF(BF17*BG17=0,0,(ROUNDUP(BF17/BG17,3))) -> 0 | BI17: =+IF($D17<>"",BI$6*$P17/$T$4*VLOOKUP($M17,CÁRNICOS!$CD$13:$CJ$48,7,FALSE),BI$5*$P17/$T$4*$BI$1) -> 0 | BJ17: =+IF($D17<>"",BJ$6*$Q17/$T$4*VLOOKUP($M17,CÁRNICOS!$CD$13:$CJ$48,7,FALSE),BJ$5*$Q17/$T$4*$BI$1) -> 0 | BK17: =+IF($D17<>"",BK$6*$R17/$T$4*VLOOKUP($M17,CÁRNICOS!$CD$13:$CJ$48,7,FALSE),BK$5*$R17/$T$4*$BI$1) -> 0 | BL17: =+IF($D17<>"",BL$6*$S17/$T$4*VLOOKUP($M17,CÁRNICOS!$CD$13:$CJ$48,7,FALSE),BL$5*$S17/$T$4*$BI$1) -> 0 | BM17: =+IF($D17<>"",BM$6*$T17/$T$4*VLOOKUP($M17,CÁRNICOS!$CD$13:$CJ$48,7,FALSE),BM$5*$T17/$T$4*$BI$1) -> 0 | BN17: =IF($J17<>"",0,SUM(BI17:BM17)) -> 0 | BO17: =+ROUNDUP(BN17/BO$4,0) -> 0 | BP17: =+IF(BN17*BO17=0,0,(ROUNDUP(BN17/BO17,3))) -> 0 | BR17: =+L17 -> 4 | BS17: =+M17 -> BELALCÁZAR | BT17: =+N17 -> INSTITUCION EDUCATIVA CRISTO REY | BU17: =+O17 -> CENTRO DOCENTE MANUELA BELTRAN | BV17: =+Z17 -> 0 | BW17: =+AH17 -> 0 | BX17: =+AP17 -> 0 | BY17: =+AX17 -> 2.538 | BZ17: =+BF17 -> 0 | CA17: =+BN17 -> 0 | CD17: =+CONSOLIDADO!C16 -> SAMANÁ (SAN DIEGO) | CE17: =+CE$11 -> 0 | CF17: =+CF$11 -> 0 | CG17: =+CG$11 -> 0 | CH17: =+CH$11 -> 1 | CI17: =+CI$11 -> 0 | CJ17: =+CJ$11 -> 0
B18: =+COUNTIF($M$8:M18,M18) -> 4 | C18: =SUM(P18:T18) -> 72 | D18: X | L18: 4 | M18: BELALCÁZAR | N18: INSTITUCION EDUCATIVA CRISTO REY | O18: ESCUELA RAFAEL POMBO | P18: 0 | Q18: 35 | R18: 37 | S18: 0 | T18: 0 | U18: =+IF($D18<>"",U$6*$P18/$T$4*VLOOKUP($M18,CÁRNICOS!$CD$13:$CJ$48,2,FALSE),U$5*$P18/$T$4*$U$1) -> 0 | V18: =+IF($D18<>"",V$6*$Q18/$T$4*VLOOKUP($M18,CÁRNICOS!$CD$13:$CJ$48,2,FALSE),V$5*$Q18/$T$4*$U$1) -> 0 | W18: =+IF($D18<>"",W$6*$R18/$T$4*VLOOKUP($M18,CÁRNICOS!$CD$13:$CJ$48,2,FALSE),W$5*$R18/$T$4*$U$1) -> 0 | X18: =+IF($D18<>"",X$6*$S18/$T$4*VLOOKUP($M18,CÁRNICOS!$CD$13:$CJ$48,2,FALSE),X$5*$S18/$T$4*$U$1) -> 0 | Y18: =+IF($D18<>"",Y$6*$T18/$T$4*VLOOKUP($M18,CÁRNICOS!$CD$13:$CJ$48,2,FALSE),Y$5*$T18/$T$4*$U$1) -> 0 | Z18: =IF($E18<>"",0,SUM(U18:Y18)) -> 0 | AA18: =+ROUNDUP(Z18/AA$4,0) -> 0 | AB18: =+IF(Z18*AA18=0,0,(ROUNDUP(Z18/AA18,3))) -> 0 | AC18: =+IF($D18<>"",AC$6*$P18/$T$4*VLOOKUP($M18,CÁRNICOS!$CD$13:$CJ$48,3,FALSE),AC$5*$P18/$T$4*$AC$1) -> 0 | AD18: =+IF($D18<>"",AD$6*$Q18/$T$4*VLOOKUP($M18,CÁRNICOS!$CD$13:$CJ$48,3,FALSE),AD$5*$Q18/$T$4*$AC$1) -> 0 | AE18: =+IF($D18<>"",AE$6*$R18/$T$4*VLOOKUP($M18,CÁRNICOS!$CD$13:$CJ$48,3,FALSE),AE$5*$R18/$T$4*$AC$1) -> 0 | AF18: =+IF($D18<>"",AF$6*$S18/$T$4*VLOOKUP($M18,CÁRNICOS!$CD$13:$CJ$48,3,FALSE),AF$5*$S18/$T$4*$AC$1) -> 0 | AG18: =+IF($D18<>"",AG$6*$T18/$T$4*VLOOKUP($M18,CÁRNICOS!$CD$13:$CJ$48,3,FALSE),AG$5*$T18/$T$4*$AC$1) -> 0 | AH18: =IF($F18<>"",0,SUM(AC18:AG18)) -> 0 | AI18: =+ROUNDUP(AH18/AI$4,0) -> 0 | AJ18: =+IF(AH18*AI18=0,0,(ROUNDUP(AH18/AI18,3))) -> 0 | AK18: =+IF($D18<>"",AK$6*$P18/$T$4*VLOOKUP($M18,CÁRNICOS!$CD$13:$CJ$48,4,FALSE),AK$5*$P18/$T$4*$AK$1) -> 0 | AL18: =+IF($D18<>"",AL$6*$Q18/$T$4*VLOOKUP($M18,CÁRNICOS!$CD$13:$CJ$48,4,FALSE),AL$5*$Q18/$T$4*$AK$1) -> 0 | AM18: =+IF($D18<>"",AM$6*$R18/$T$4*VLOOKUP($M18,CÁRNICOS!$CD$13:$CJ$48,4,FALSE),AM$5*$R18/$T$4*$AK$1) -> 0 | AN18: =+IF($D18<>"",AN$6*$S18/$T$4*VLOOKUP($M18,CÁRNICOS!$CD$13:$CJ$48,4,FALSE),AN$5*$S18/$T$4*$AK$1) -> 0 | AO18: =+IF($D18<>"",AO$6*$T18/$T$4*VLOOKUP($M18,CÁRNICOS!$CD$13:$CJ$48,4,FALSE),AO$5*$T18/$T$4*$AK$1) -> 0 | AP18: =IF($G18<>"",0,SUM(AK18:AO18)) -> 0 | AQ18: =+ROUNDUP(AP18/AQ$4,0) -> 0 | AR18: =+IF(AP18*AQ18=0,0,(ROUNDUP(AP18/AQ18,3))) -> 0 | AS18: =+IF($D18<>"",AS$6*$P18/$T$4*VLOOKUP($M18,CÁRNICOS!$CD$13:$CJ$48,5,FALSE),AS$5*$P18/$T$4*$AS$1) -> 0 | AT18: =+IF($D18<>"",AT$6*$Q18/$T$4*VLOOKUP($M18,CÁRNICOS!$CD$13:$CJ$48,5,FALSE),AT$5*$Q18/$T$4*$AS$1) -> 1.89 | AU18: =+IF($D18<>"",AU$6*$R18/$T$4*VLOOKUP($M18,CÁRNICOS!$CD$13:$CJ$48,5,FALSE),AU$5*$R18/$T$4*$AS$1) -> 2.405 | AV18: =+IF($D18<>"",AV$6*$S18/$T$4*VLOOKUP($M18,CÁRNICOS!$CD$13:$CJ$48,5,FALSE),AV$5*$S18/$T$4*$AS$1) -> 0 | AW18: =+IF($D18<>"",AW$6*$T18/$T$4*VLOOKUP($M18,CÁRNICOS!$CD$13:$CJ$48,5,FALSE),AW$5*$T18/$T$4*$AS$1) -> 0 | AX18: =IF($H18<>"",0,SUM(AS18:AW18)) -> 4.295 | AY18: =+ROUNDUP(AX18/AY$4,0) -> 1 | AZ18: =+IF(AX18*AY18=0,0,(ROUNDUP(AX18/AY18,3))) -> 4.295 | BA18: =+IF($D18<>"",BA$6*$P18/$T$4*VLOOKUP($M18,CÁRNICOS!$CD$13:$CJ$48,6,FALSE),BA$5*$P18/$T$4*$BA$1) -> 0 | BB18: =+IF($D18<>"",BB$6*$Q18/$T$4*VLOOKUP($M18,CÁRNICOS!$CD$13:$CJ$48,6,FALSE),BB$5*$Q18/$T$4*$BA$1) -> 0 | BC18: =+IF($D18<>"",BC$6*$R18/$T$4*VLOOKUP($M18,CÁRNICOS!$CD$13:$CJ$48,6,FALSE),BC$5*$R18/$T$4*$BA$1) -> 0 | BD18: =+IF($D18<>"",BD$6*$S18/$T$4*VLOOKUP($M18,CÁRNICOS!$CD$13:$CJ$48,6,FALSE),BD$5*$S18/$T$4*$BA$1) -> 0 | BE18: =+IF($D18<>"",BE$6*$T18/$T$4*VLOOKUP($M18,CÁRNICOS!$CD$13:$CJ$48,6,FALSE),BE$5*$T18/$T$4*$BA$1) -> 0 | BF18: =IF($I18<>"",0,SUM(BA18:BE18)) -> 0 | BG18: =+ROUNDUP(BF18/BG$4,0) -> 0 | BH18: =+IF(BF18*BG18=0,0,(ROUNDUP(BF18/BG18,3))) -> 0 | BI18: =+IF($D18<>"",BI$6*$P18/$T$4*VLOOKUP($M18,CÁRNICOS!$CD$13:$CJ$48,7,FALSE),BI$5*$P18/$T$4*$BI$1) -> 0 | BJ18: =+IF($D18<>"",BJ$6*$Q18/$T$4*VLOOKUP($M18,CÁRNICOS!$CD$13:$CJ$48,7,FALSE),BJ$5*$Q18/$T$4*$BI$1) -> 0 | BK18: =+IF($D18<>"",BK$6*$R18/$T$4*VLOOKUP($M18,CÁRNICOS!$CD$13:$CJ$48,7,FALSE),BK$5*$R18/$T$4*$BI$1) -> 0 | BL18: =+IF($D18<>"",BL$6*$S18/$T$4*VLOOKUP($M18,CÁRNICOS!$CD$13:$CJ$48,7,FALSE),BL$5*$S18/$T$4*$BI$1) -> 0 | BM18: =+IF($D18<>"",BM$6*$T18/$T$4*VLOOKUP($M18,CÁRNICOS!$CD$13:$CJ$48,7,FALSE),BM$5*$T18/$T$4*$BI$1) -> 0 | BN18: =IF($J18<>"",0,SUM(BI18:BM18)) -> 0 | BO18: =+ROUNDUP(BN18/BO$4,0) -> 0 | BP18: =+IF(BN18*BO18=0,0,(ROUNDUP(BN18/BO18,3))) -> 0 | BR18: =+L18 -> 4 | BS18: =+M18 -> BELALCÁZAR | BT18: =+N18 -> INSTITUCION EDUCATIVA CRISTO REY | BU18: =+O18 -> ESCUELA RAFAEL POMBO | BV18: =+Z18 -> 0 | BW18: =+AH18 -> 0 | BX18: =+AP18 -> 0 | BY18: =+AX18 -> 4.295 | BZ18: =+BF18 -> 0 | CA18: =+BN18 -> 0 | CD18: =+CONSOLIDADO!C17 -> SAMANÁ (BERLÍN) | CE18: =+CE$11 -> 0 | CF18: =+CF$11 -> 0 | CG18: =+CG$11 -> 0 | CH18: =+CH$11 -> 1 | CI18: =+CI$11 -> 0 | CJ18: =+CJ$11 -> 0
B19: =+COUNTIF($M$8:M19,M19) -> 1 | C19: =SUM(P19:T19) -> 60 | D19: X | L19: U1 | M19: CHINCHINÁ | N19: INSTITUCION EDUCATIVA BARTOLOME MITRE | O19: INSTITUCION EDUCATIVA BARTOLOME MITRE - SEDE PRINCIPAL | P19: 0 | Q19: 0 | R19: 0 | S19: 50 | T19: 10 | U19: =+IF($D19<>"",U$6*$P19/$T$4*VLOOKUP($M19,CÁRNICOS!$CD$13:$CJ$48,2,FALSE),U$5*$P19/$T$4*$U$1) -> 0 | V19: =+IF($D19<>"",V$6*$Q19/$T$4*VLOOKUP($M19,CÁRNICOS!$CD$13:$CJ$48,2,FALSE),V$5*$Q19/$T$4*$U$1) -> 0 | W19: =+IF($D19<>"",W$6*$R19/$T$4*VLOOKUP($M19,CÁRNICOS!$CD$13:$CJ$48,2,FALSE),W$5*$R19/$T$4*$U$1) -> 0 | X19: =+IF($D19<>"",X$6*$S19/$T$4*VLOOKUP($M19,CÁRNICOS!$CD$13:$CJ$48,2,FALSE),X$5*$S19/$T$4*$U$1) -> 0 | Y19: =+IF($D19<>"",Y$6*$T19/$T$4*VLOOKUP($M19,CÁRNICOS!$CD$13:$CJ$48,2,FALSE),Y$5*$T19/$T$4*$U$1) -> 0 | Z19: =IF($E19<>"",0,SUM(U19:Y19)) -> 0 | AA19: =+ROUNDUP(Z19/AA$4,0) -> 0 | AB19: =+IF(Z19*AA19=0,0,(ROUNDUP(Z19/AA19,3))) -> 0 | AC19: =+IF($D19<>"",AC$6*$P19/$T$4*VLOOKUP($M19,CÁRNICOS!$CD$13:$CJ$48,3,FALSE),AC$5*$P19/$T$4*$AC$1) -> 0 | AD19: =+IF($D19<>"",AD$6*$Q19/$T$4*VLOOKUP($M19,CÁRNICOS!$CD$13:$CJ$48,3,FALSE),AD$5*$Q19/$T$4*$AC$1) -> 0 | AE19: =+IF($D19<>"",AE$6*$R19/$T$4*VLOOKUP($M19,CÁRNICOS!$CD$13:$CJ$48,3,FALSE),AE$5*$R19/$T$4*$AC$1) -> 0 | AF19: =+IF($D19<>"",AF$6*$S19/$T$4*VLOOKUP($M19,CÁRNICOS!$CD$13:$CJ$48,3,FALSE),AF$5*$S19/$T$4*$AC$1) -> 0 | AG19: =+IF($D19<>"",AG$6*$T19/$T$4*VLOOKUP($M19,CÁRNICOS!$CD$13:$CJ$48,3,FALSE),AG$5*$T19/$T$4*$AC$1) -> 0 | AH19: =IF($F19<>"",0,SUM(AC19:AG19)) -> 0 | AI19: =+ROUNDUP(AH19/AI$4,0) -> 0 | AJ19: =+IF(AH19*AI19=0,0,(ROUNDUP(AH19/AI19,3))) -> 0 | AK19: =+IF($D19<>"",AK$6*$P19/$T$4*VLOOKUP($M19,CÁRNICOS!$CD$13:$CJ$48,4,FALSE),AK$5*$P19/$T$4*$AK$1) -> 0 | AL19: =+IF($D19<>"",AL$6*$Q19/$T$4*VLOOKUP($M19,CÁRNICOS!$CD$13:$CJ$48,4,FALSE),AL$5*$Q19/$T$4*$AK$1) -> 0 | AM19: =+IF($D19<>"",AM$6*$R19/$T$4*VLOOKUP($M19,CÁRNICOS!$CD$13:$CJ$48,4,FALSE),AM$5*$R19/$T$4*$AK$1) -> 0 | AN19: =+IF($D19<>"",AN$6*$S19/$T$4*VLOOKUP($M19,CÁRNICOS!$CD$13:$CJ$48,4,FALSE),AN$5*$S19/$T$4*$AK$1) -> 0 | AO19: =+IF($D19<>"",AO$6*$T19/$T$4*VLOOKUP($M19,CÁRNICOS!$CD$13:$CJ$48,4,FALSE),AO$5*$T19/$T$4*$AK$1) -> 0 | AP19: =IF($G19<>"",0,SUM(AK19:AO19)) -> 0 | AQ19: =+ROUNDUP(AP19/AQ$4,0) -> 0 | AR19: =+IF(AP19*AQ19=0,0,(ROUNDUP(AP19/AQ19,3))) -> 0 | AS19: =+IF($D19<>"",AS$6*$P19/$T$4*VLOOKUP($M19,CÁRNICOS!$CD$13:$CJ$48,5,FALSE),AS$5*$P19/$T$4*$AS$1) -> 0 | AT19: =+IF($D19<>"",AT$6*$Q19/$T$4*VLOOKUP($M19,CÁRNICOS!$CD$13:$CJ$48,5,FALSE),AT$5*$Q19/$T$4*$AS$1) -> 0 | AU19: =+IF($D19<>"",AU$6*$R19/$T$4*VLOOKUP($M19,CÁRNICOS!$CD$13:$CJ$48,5,FALSE),AU$5*$R19/$T$4*$AS$1) -> 0 | AV19: =+IF($D19<>"",AV$6*$S19/$T$4*VLOOKUP($M19,CÁRNICOS!$CD$13:$CJ$48,5,FALSE),AV$5*$S19/$T$4*$AS$1) -> 4 | AW19: =+IF($D19<>"",AW$6*$T19/$T$4*VLOOKUP($M19,CÁRNICOS!$CD$13:$CJ$48,5,FALSE),AW$5*$T19/$T$4*$AS$1) -> 1 | AX19: =IF($H19<>"",0,SUM(AS19:AW19)) -> 5 | AY19: =+ROUNDUP(AX19/AY$4,0) -> 1 | AZ19: =+IF(AX19*AY19=0,0,(ROUNDUP(AX19/AY19,3))) -> 5 | BA19: =+IF($D19<>"",BA$6*$P19/$T$4*VLOOKUP($M19,CÁRNICOS!$CD$13:$CJ$48,6,FALSE),BA$5*$P19/$T$4*$BA$1) -> 0 | BB19: =+IF($D19<>"",BB$6*$Q19/$T$4*VLOOKUP($M19,CÁRNICOS!$CD$13:$CJ$48,6,FALSE),BB$5*$Q19/$T$4*$BA$1) -> 0 | BC19: =+IF($D19<>"",BC$6*$R19/$T$4*VLOOKUP($M19,CÁRNICOS!$CD$13:$CJ$48,6,FALSE),BC$5*$R19/$T$4*$BA$1) -> 0 | BD19: =+IF($D19<>"",BD$6*$S19/$T$4*VLOOKUP($M19,CÁRNICOS!$CD$13:$CJ$48,6,FALSE),BD$5*$S19/$T$4*$BA$1) -> 0 | BE19: =+IF($D19<>"",BE$6*$T19/$T$4*VLOOKUP($M19,CÁRNICOS!$CD$13:$CJ$48,6,FALSE),BE$5*$T19/$T$4*$BA$1) -> 0 | BF19: =IF($I19<>"",0,SUM(BA19:BE19)) -> 0 | BG19: =+ROUNDUP(BF19/BG$4,0) -> 0 | BH19: =+IF(BF19*BG19=0,0,(ROUNDUP(BF19/BG19,3))) -> 0 | BI19: =+IF($D19<>"",BI$6*$P19/$T$4*VLOOKUP($M19,CÁRNICOS!$CD$13:$CJ$48,7,FALSE),BI$5*$P19/$T$4*$BI$1) -> 0 | BJ19: =+IF($D19<>"",BJ$6*$Q19/$T$4*VLOOKUP($M19,CÁRNICOS!$CD$13:$CJ$48,7,FALSE),BJ$5*$Q19/$T$4*$BI$1) -> 0 | BK19: =+IF($D19<>"",BK$6*$R19/$T$4*VLOOKUP($M19,CÁRNICOS!$CD$13:$CJ$48,7,FALSE),BK$5*$R19/$T$4*$BI$1) -> 0 | BL19: =+IF($D19<>"",BL$6*$S19/$T$4*VLOOKUP($M19,CÁRNICOS!$CD$13:$CJ$48,7,FALSE),BL$5*$S19/$T$4*$BI$1) -> 0 | BM19: =+IF($D19<>"",BM$6*$T19/$T$4*VLOOKUP($M19,CÁRNICOS!$CD$13:$CJ$48,7,FALSE),BM$5*$T19/$T$4*$BI$1) -> 0 | BN19: =IF($J19<>"",0,SUM(BI19:BM19)) -> 0 | BO19: =+ROUNDUP(BN19/BO$4,0) -> 0 | BP19: =+IF(BN19*BO19=0,0,(ROUNDUP(BN19/BO19,3))) -> 0 | BR19: =+L19 -> U1 | BS19: =+M19 -> CHINCHINÁ | BT19: =+N19 -> INSTITUCION EDUCATIVA BARTOLOME MITRE | BU19: =+O19 -> INSTITUCION EDUCATIVA BARTOLOME MITRE - SEDE PRINCIPAL | BV19: =+Z19 -> 0 | BW19: =+AH19 -> 0 | BX19: =+AP19 -> 0 | BY19: =+AX19 -> 5 | BZ19: =+BF19 -> 0 | CA19: =+BN19 -> 0 | CD19: =+CONSOLIDADO!C18 -> VICTORIA | CE19: =+CE$11 -> 0 | CF19: =+CF$11 -> 0 | CG19: =+CG$11 -> 0 | CH19: =+CH$11 -> 1 | CI19: =+CI$11 -> 0 | CJ19: =+CJ$11 -> 0
